Workbook

Sheet HUONG_DAN
A1: HƯỚNG DẪN – FILE VẬN HÀNH KÊNH CHỊ GIANG HIỂU CHUYỆN
A2: Hỏi đáp sinh lý – vợ chồng cho đàn ông 45+ · Affiliate Shopee · Facebook Reels · lập ngày 16/10/2026
A4: Mục tiêu
B5: Mục tiêu sản lượng | C5: 8 video/ngày từ tuần 4 (≈240 video/tháng), mỗi video có link Shopee kèm Sub_id riêng
B6: Chỉ số chính | C6: Hoa hồng Shopee affiliate mỗi tuần (xem TONG_QUAN)
B7: Bắt đầu | C7: Giai đoạn 0 dựng nền 16–18/10 · Tuần 1 bắt đầu thứ Hai 19/10/2026 · lộ trình 12 tuần đến 10/01/2027
A9: Bốn điều cần biết trước khi chạy
B10: 1. Hoa hồng tính theo Shopee, không theo TikTok | C10: Tên, giá, hoa hồng ở SAN_PHAM lấy đúng sản phẩm trong link Shopee. Thực phẩm chức năng trên Shopee thường chỉ 2,5–7,5% (TikTok 10–15%), nên thứ hạng đã đổi. Hoa hồng/đơn cao nhất hiện tại: Viên Thận Botamax ~46k, Quần boxer nam thông hơi Natural Breath (combo 3) ~42k, Máy đo huyết áp Omron HEM-7180 ~42k, Viên Bổ Thận DSD Sâm Nhung ~38k, Gối massage hồng ngoại Kingtech KP-315 ~30k.
B11: 2. Mỗi video một Sub_id | C11: Cột I của KHO_KICH_BAN tự tạo link dạng …?sub_id=ChiGiang-<ID video>-FBReels-SP<mã SP>. Dán đúng link này vào bình luận gốc thì báo cáo Shopee cho biết video nào ra đơn – không cần đoán.
B12: 3. Một page, nội dung nhạy cảm | C12: Chị Giang Hiểu Chuyện là page duy nhất của dự án: bị hạn chế là mất hết. Giữ giọng chia sẻ kiến thức, không xưng bác sĩ, không hình gợi dục, không hứa “tăng sinh lý” (QC điểm 3–5).
B13: 4. Bài toán kinh tế chưa được chứng minh | C13: Với giả định 5.000 view/video, hoa hồng khi đủ 8 video/ngày khoảng 6.6 triệu/tháng, trong khi 4 người tốn khoảng 32 triệu/tháng. Ngưỡng hòa vốn ≈ 24.248 view/video. Giai đoạn 1 chạy 2 người kiêm nhiệm; lấy số thật của page ngay (việc T08).
A15: Quy ước màu
B16: Chữ xanh dương, nền vàng nhạt | C16: Ô cần điền hoặc chọn – chỉ sửa những ô này
B17: Chữ đen | C17: Công thức – không sửa, tự tính
B18: Chữ xanh lá | C18: Công thức lấy dữ liệu từ sheet khác
B19: Nền đỏ nhạt | C19: Cần xử lý (quá hạn, dưới ngưỡng, link cần sửa)
A21: Ai dùng sheet nào
B22: Điều phối kiêm trưởng nội dung (R1) | C22: TONG_QUAN mỗi sáng · KHO_KICH_BAN (duyệt: đổi trạng thái) · LO_TRINH · CONG_VIEC · DU_BAO · review Chủ nhật
B23: Biên kịch – master prompt (R2) | C23: KHO_KICH_BAN: nhận dòng “Ý tưởng” → viết prompt → đổi sang “Chờ duyệt”. Khuôn và luật giọng nói ở KENH, mẫu ở TAI_NGUYEN
B24: Sản xuất video (R3) | C24: KHO_KICH_BAN: lọc “Đã duyệt” → Viral Studio → “Đang sản xuất” → “QC”
B25: Đăng bài, cộng đồng & dữ liệu (R4) | C25: KHO_KICH_BAN: lọc “QC” → kiểm 10 điểm (QUY_TRINH) → Postiz, dán link cột I vào bình luận gốc → “Đã đăng”. SAN_PHAM (trạng thái link) · THEO_DOI_NGAY (nhập số mỗi sáng)
B26: Mọi người | C26: NGUON_CONTENT: thấy video, kênh, hook hay thì dán link + ghi “Học được gì”. Trang HTML (tab Nguồn content) dán link là xem ngay
A28: Luồng một video
B29: Trạng thái | C29: Ý tưởng → Đang viết → Chờ duyệt → Cần sửa → Đã duyệt → Đang sản xuất → QC → Sẵn sàng đăng → Đã đăng (hoặc Hủy)
B30: Cập nhật file | C30: File HTML “du-an-chi-giang.html” là bản trực quan để xem và giao việc; số liệu sống nằm ở file Excel này. Chạy python build.py chỉ làm mới file HTML; file Excel chỉ tạo lại khi chạy python build.py excel (sẽ xóa số liệu đã nhập).

Sheet TONG_QUAN
A1: TỔNG QUAN ĐIỀU HÀNH
A2: Mở mỗi sáng. Mọi số đều tự tính từ các sheet khác – không nhập tay ở đây.
A3: Chỉ số chính
A4: Video kế hoạch đến hôm nay | B4: =SUMIFS(THEO_DOI_NGAY!$C$5:$C$88,THEO_DOI_NGAY!$A$5:$A$88,"<="&TODAY())
A5: Video đã đăng | B5: =SUM(THEO_DOI_NGAY!$D$5:$D$88)
A6: % hoàn thành kế hoạch | B6: =IF(B4=0,"",B5/B4)
A7: Tổng view | B7: =SUM(THEO_DOI_NGAY!$F$5:$F$88)
A8: Tổng click | B8: =SUM(THEO_DOI_NGAY!$G$5:$G$88)
A9: Tổng đơn | B9: =SUM(THEO_DOI_NGAY!$H$5:$H$88)
A10: Tổng hoa hồng (đ) | B10: =SUM(THEO_DOI_NGAY!$I$5:$I$88)
A11: Hoa hồng/video đã đăng (đ) | B11: =IF(B5=0,"",B10/B5)
A12: Hoa hồng 7 ngày gần nhất (đ) | B12: =SUMIFS(THEO_DOI_NGAY!$I$5:$I$88,THEO_DOI_NGAY!$A$5:$A$88,">"&(TODAY()-7),THEO_DOI_NGAY!$A$5:$A$88,"<="&TODAY())
A15: Theo trụ cột (từ KHO_KICH_BAN, video “Đã đăng”)
A16: Trụ cột | B16: Video/ngày hiện tại | C16: Đã đăng | D16: View | E16: Click | F16: Đơn | G16: Click/View | H16: Đơn/video
A17: T1 · Phong độ & tiết niệu | B17: =IFERROR(INDEX(LO_TRINH!D$4:D$15,MATCH(TODAY(),LO_TRINH!$B$4:$B$15,1)),0) | C17: =COUNTIFS(KHO_KICH_BAN!$B$5:$B$404,"T1",KHO_KICH_BAN!$M$5:$M$404,"Đã đăng") | D17: =SUMIFS(KHO_KICH_BAN!$Q$5:$Q$404,KHO_KICH_BAN!$B$5:$B$404,"T1",KHO_KICH_BAN!$M$5:$M$404,"Đã đăng") | E17: =SUMIFS(KHO_KICH_BAN!$R$5:$R$404,KHO_KICH_BAN!$B$5:$B$404,"T1",KHO_KICH_BAN!$M$5:$M$404,"Đã đăng") | F17: =SUMIFS(KHO_KICH_BAN!$S$5:$S$404,KHO_KICH_BAN!$B$5:$B$404,"T1",KHO_KICH_BAN!$M$5:$M$404,"Đã đăng") | G17: =IF(D17=0,"",E17/D17) | H17: =IF(C17=0,"",F17/C17)
A18: T2 · Chuyện vợ chồng | B18: =IFERROR(INDEX(LO_TRINH!E$4:E$15,MATCH(TODAY(),LO_TRINH!$B$4:$B$15,1)),0) | C18: =COUNTIFS(KHO_KICH_BAN!$B$5:$B$404,"T2",KHO_KICH_BAN!$M$5:$M$404,"Đã đăng") | D18: =SUMIFS(KHO_KICH_BAN!$Q$5:$Q$404,KHO_KICH_BAN!$B$5:$B$404,"T2",KHO_KICH_BAN!$M$5:$M$404,"Đã đăng") | E18: =SUMIFS(KHO_KICH_BAN!$R$5:$R$404,KHO_KICH_BAN!$B$5:$B$404,"T2",KHO_KICH_BAN!$M$5:$M$404,"Đã đăng") | F18: =SUMIFS(KHO_KICH_BAN!$S$5:$S$404,KHO_KICH_BAN!$B$5:$B$404,"T2",KHO_KICH_BAN!$M$5:$M$404,"Đã đăng") | G18: =IF(D18=0,"",E18/D18) | H18: =IF(C18=0,"",F18/C18)
A19: T3 · Bệnh nền & chuyện ấy | B19: =IFERROR(INDEX(LO_TRINH!F$4:F$15,MATCH(TODAY(),LO_TRINH!$B$4:$B$15,1)),0) | C19: =COUNTIFS(KHO_KICH_BAN!$B$5:$B$404,"T3",KHO_KICH_BAN!$M$5:$M$404,"Đã đăng") | D19: =SUMIFS(KHO_KICH_BAN!$Q$5:$Q$404,KHO_KICH_BAN!$B$5:$B$404,"T3",KHO_KICH_BAN!$M$5:$M$404,"Đã đăng") | E19: =SUMIFS(KHO_KICH_BAN!$R$5:$R$404,KHO_KICH_BAN!$B$5:$B$404,"T3",KHO_KICH_BAN!$M$5:$M$404,"Đã đăng") | F19: =SUMIFS(KHO_KICH_BAN!$S$5:$S$404,KHO_KICH_BAN!$B$5:$B$404,"T3",KHO_KICH_BAN!$M$5:$M$404,"Đã đăng") | G19: =IF(D19=0,"",E19/D19) | H19: =IF(C19=0,"",F19/C19)
A20: T4 · Phong độ bề ngoài | B20: =IFERROR(INDEX(LO_TRINH!G$4:G$15,MATCH(TODAY(),LO_TRINH!$B$4:$B$15,1)),0) | C20: =COUNTIFS(KHO_KICH_BAN!$B$5:$B$404,"T4",KHO_KICH_BAN!$M$5:$M$404,"Đã đăng") | D20: =SUMIFS(KHO_KICH_BAN!$Q$5:$Q$404,KHO_KICH_BAN!$B$5:$B$404,"T4",KHO_KICH_BAN!$M$5:$M$404,"Đã đăng") | E20: =SUMIFS(KHO_KICH_BAN!$R$5:$R$404,KHO_KICH_BAN!$B$5:$B$404,"T4",KHO_KICH_BAN!$M$5:$M$404,"Đã đăng") | F20: =SUMIFS(KHO_KICH_BAN!$S$5:$S$404,KHO_KICH_BAN!$B$5:$B$404,"T4",KHO_KICH_BAN!$M$5:$M$404,"Đã đăng") | G20: =IF(D20=0,"",E20/D20) | H20: =IF(C20=0,"",F20/C20)
A21: T5 · Sống khỏe tuổi 50+ | B21: =IFERROR(INDEX(LO_TRINH!H$4:H$15,MATCH(TODAY(),LO_TRINH!$B$4:$B$15,1)),0) | C21: =COUNTIFS(KHO_KICH_BAN!$B$5:$B$404,"T5",KHO_KICH_BAN!$M$5:$M$404,"Đã đăng") | D21: =SUMIFS(KHO_KICH_BAN!$Q$5:$Q$404,KHO_KICH_BAN!$B$5:$B$404,"T5",KHO_KICH_BAN!$M$5:$M$404,"Đã đăng") | E21: =SUMIFS(KHO_KICH_BAN!$R$5:$R$404,KHO_KICH_BAN!$B$5:$B$404,"T5",KHO_KICH_BAN!$M$5:$M$404,"Đã đăng") | F21: =SUMIFS(KHO_KICH_BAN!$S$5:$S$404,KHO_KICH_BAN!$B$5:$B$404,"T5",KHO_KICH_BAN!$M$5:$M$404,"Đã đăng") | G21: =IF(D21=0,"",E21/D21) | H21: =IF(C21=0,"",F21/C21)
A22: Tổng | B22: =SUM(B17:B21) | C22: =SUM(C17:C21) | D22: =SUM(D17:D21) | E22: =SUM(E17:E21) | F22: =SUM(F17:F21) | G22: =IF(D22=0,"",E22/D22) | H22: =IF(C22=0,"",F22/C22)
A24: Theo loại video
A25: Loại video | B25: Đã đăng | C25: View TB | D25: Đơn | E25: Đơn/video
A26: Hỏi đáp | B26: =COUNTIFS(KHO_KICH_BAN!$C$5:$C$404,A26,KHO_KICH_BAN!$M$5:$M$404,"Đã đăng") | C26: =IF(B26=0,"",SUMIFS(KHO_KICH_BAN!$Q$5:$Q$404,KHO_KICH_BAN!$C$5:$C$404,A26,KHO_KICH_BAN!$M$5:$M$404,"Đã đăng")/B26) | D26: =SUMIFS(KHO_KICH_BAN!$S$5:$S$404,KHO_KICH_BAN!$C$5:$C$404,A26,KHO_KICH_BAN!$M$5:$M$404,"Đã đăng") | E26: =IF(B26=0,"",D26/B26)
A27: Hỏi đáp gắn SP | B27: =COUNTIFS(KHO_KICH_BAN!$C$5:$C$404,A27,KHO_KICH_BAN!$M$5:$M$404,"Đã đăng") | C27: =IF(B27=0,"",SUMIFS(KHO_KICH_BAN!$Q$5:$Q$404,KHO_KICH_BAN!$C$5:$C$404,A27,KHO_KICH_BAN!$M$5:$M$404,"Đã đăng")/B27) | D27: =SUMIFS(KHO_KICH_BAN!$S$5:$S$404,KHO_KICH_BAN!$C$5:$C$404,A27,KHO_KICH_BAN!$M$5:$M$404,"Đã đăng") | E27: =IF(B27=0,"",D27/B27)
A28: Review sản phẩm | B28: =COUNTIFS(KHO_KICH_BAN!$C$5:$C$404,A28,KHO_KICH_BAN!$M$5:$M$404,"Đã đăng") | C28: =IF(B28=0,"",SUMIFS(KHO_KICH_BAN!$Q$5:$Q$404,KHO_KICH_BAN!$C$5:$C$404,A28,KHO_KICH_BAN!$M$5:$M$404,"Đã đăng")/B28) | D28: =SUMIFS(KHO_KICH_BAN!$S$5:$S$404,KHO_KICH_BAN!$C$5:$C$404,A28,KHO_KICH_BAN!$M$5:$M$404,"Đã đăng") | E28: =IF(B28=0,"",D28/B28)
A29: Tình huống vợ chồng | B29: =COUNTIFS(KHO_KICH_BAN!$C$5:$C$404,A29,KHO_KICH_BAN!$M$5:$M$404,"Đã đăng") | C29: =IF(B29=0,"",SUMIFS(KHO_KICH_BAN!$Q$5:$Q$404,KHO_KICH_BAN!$C$5:$C$404,A29,KHO_KICH_BAN!$M$5:$M$404,"Đã đăng")/B29) | D29: =SUMIFS(KHO_KICH_BAN!$S$5:$S$404,KHO_KICH_BAN!$C$5:$C$404,A29,KHO_KICH_BAN!$M$5:$M$404,"Đã đăng") | E29: =IF(B29=0,"",D29/B29)
A30: Từ bình luận | B30: =COUNTIFS(KHO_KICH_BAN!$C$5:$C$404,A30,KHO_KICH_BAN!$M$5:$M$404,"Đã đăng") | C30: =IF(B30=0,"",SUMIFS(KHO_KICH_BAN!$Q$5:$Q$404,KHO_KICH_BAN!$C$5:$C$404,A30,KHO_KICH_BAN!$M$5:$M$404,"Đã đăng")/B30) | D30: =SUMIFS(KHO_KICH_BAN!$S$5:$S$404,KHO_KICH_BAN!$C$5:$C$404,A30,KHO_KICH_BAN!$M$5:$M$404,"Đã đăng") | E30: =IF(B30=0,"",D30/B30)
A32: Dây chuyền kịch bản (KHO_KICH_BAN)
A33: Trạng thái | B33: Số video
A34: Ý tưởng | B34: =COUNTIF(KHO_KICH_BAN!$M$5:$M$404,A34)
A35: Đang viết | B35: =COUNTIF(KHO_KICH_BAN!$M$5:$M$404,A35)
A36: Chờ duyệt | B36: =COUNTIF(KHO_KICH_BAN!$M$5:$M$404,A36)
A37: Cần sửa | B37: =COUNTIF(KHO_KICH_BAN!$M$5:$M$404,A37)
A38: Đã duyệt | B38: =COUNTIF(KHO_KICH_BAN!$M$5:$M$404,A38)
A39: Đang sản xuất | B39: =COUNTIF(KHO_KICH_BAN!$M$5:$M$404,A39)
A40: QC | B40: =COUNTIF(KHO_KICH_BAN!$M$5:$M$404,A40)
A41: Sẵn sàng đăng | B41: =COUNTIF(KHO_KICH_BAN!$M$5:$M$404,A41)
A42: Đã đăng | B42: =COUNTIF(KHO_KICH_BAN!$M$5:$M$404,A42)
A43: Hủy | B43: =COUNTIF(KHO_KICH_BAN!$M$5:$M$404,A43)
A45: Việc cần chú ý
...

Sheet KENH
A1: KÊNH CHỊ GIANG HIỂU CHUYỆN – HỒ SƠ & 5 TRỤ CỘT
A2: Một kênh, chia nội dung thành 5 trụ cột. Số video/ngày của từng trụ cột lấy từ LO_TRINH.
A4: Hồ sơ kênh
B5: Tên page | C5: Chị Giang Hiểu Chuyện
B6: Postiz ID | C6: cmup0vxri0002qxtax0kkxduf
B7: Thư mục video | C7: D:\video-ai-aff\viral-studio-downloads\videos\gioi-tinh
B8: Trạng thái | C8: Đang chạy, đã có ~150 video hỏi đáp; chưa có script Postiz tự động cho page này
B9: Nhân vật | C9: Chị Giang (ảnh chuẩn chi-giang-loat-2/nhan-vat-chi.png): áo scrubs xanh ngọc cổ V, tóc nâu đen dài, xưng “chị”. Vai phụ: “cô bạn lo lắng” (cùng gương mặt, kính đen tròn, áo hoa) hoặc người chồng.
B10: Định dạng | C10: Hỏi đáp “Chị ơi, cho em hỏi thầm…”: 70 giây · 7 shot · băng chữ đỏ ghi câu hỏi. Review sản phẩm: 50 giây · 5 shot · sản phẩm trong tay từ giây đầu.
B11: Công cụ | C11: Viral Studio (studio_create, nguyên văn master prompt + ảnh nhân vật) → xuất MP4 9:16 → Postiz
A13: Tệp khán giả (Facebook Insights lifetime, 16/10/2026)
B14: Giới tính | C14: Nam ~90%
B15: Tuổi | C15: 45–54: 27,1% · 55–64: 25,3% · 65+: 20,3% · 35–44: 15,3% → 73% từ 45 tuổi
B16: Quốc gia | C16: Việt Nam 92% · Mỹ 6,2% (kiều bào, đang tăng)
B17: Thành phố | C17: TP.HCM 53,3% (tăng 5 điểm trong 3 ngày) · Hà Nội 8% · Quảng Nam 8% · Đà Nẵng 5,8% · Cà Mau 5,3%
A19: Luật giọng nói (áp vào mọi prompt)
B20: • | C20: Chị xưng “chị”, gọi người xem là “mấy anh”, “anh”; người hỏi gọi “chị ơi”
B21: • | C21: KHÔNG xưng hay được gọi là bác sĩ, dược sĩ, chuyên gia; không áo blouse, không ống nghe
B22: • | C22: Giọng và từ ngữ miền Nam, nhịp chậm, chữ to; tránh tiếng lóng giới trẻ
B23: • | C23: Nói kiểu chia sẻ kiến thức: không tục, không tả hành vi chi tiết, không hình gợi dục
B24: • | C24: Sản phẩm: video hỏi đáp nhắc đúng 1 lần ở cuối; chỉ nói “hỗ trợ” + triệu chứng, không “chữa”, không “tăng sinh lý”
A26: 5 trụ cột nội dung
A27: Mã | B27: Trụ cột | C27: Nội dung | D27: Câu hỏi mẫu | E27: Sản phẩm chủ lực (mã SP) | F27: Video/ngày (tuần 12) | G27: Phụ trách viết
A28: T1 | B28: Phong độ & tiết niệu | C28: Tiểu đêm, tiền liệt tuyến, ra ít, hết hứng tuổi 50, rượu thuốc, kẽm | D28: • Đêm dậy tiểu 3–4 lần là bị gì? • Ngoài 50 ra ít, loãng là thiếu gì? • Về hưu tự nhiên hết hứng, tại sao? | E28: 4. Viên Thận Botamax 1. Kẽm DSD Multi Ginseng B+ Plus 150mg (60 viên) 5. Kẽm ADA 150mg 3. Vương Bảo Thái Minh (tiền liệt tuyến) 2. Viên Bổ Thận DSD Sâm Nhung | F28: =LO_TRINH!D15
A29: T2 | B29: Chuyện vợ chồng | C29: Vợ mãn kinh, vợ khô, vợ né chồng, hiểu vợ, vệ sinh trước khi gần | D29: • Vợ mãn kinh né chồng có phải hết thương? • Vợ nói “em mệt” là thật hay giả? • Bao lâu không gần nhau là báo động? | E29: 6. Bọt vệ sinh nam Oniiz (combo) 20. Gối massage hồng ngoại Kingtech KP-315 23. Trà mâm xôi sâm tố nữ A Nam 8. Bao cao su Durex Performa | F29: =LO_TRINH!E15
A30: T3 | B30: Bệnh nền & chuyện ấy | C30: Huyết áp, tiểu đường, mỡ máu, đau lưng, mất ngủ, chuột rút ảnh hưởng chuyện vợ chồng | D30: • Uống thuốc huyết áp có làm yếu chuyện ấy? • Đau lưng thoát vị có nên gần vợ? • Đêm chuột rút bắp chân là thiếu gì? | E30: 11. Máy đo huyết áp Omron HEM-7180 19. Đai lưng tự nóng Kazumi 12. Máy đo huyết áp AICARE X1 có giọng nói 13. Viên dây thìa canh Diabetna (tiểu đường) 15. Viên magie hữu cơ + B6 14. Miếng dán chân Ông Lão Bắc Kinh 9. Gel xoa bóp xương khớp Phục Thể An (Musecos) 10. Linh Chi Thiên Ma Thấu Cốt Hoàn | F30: =LO_TRINH!F15
A31: T4 | B31: Phong độ bề ngoài | C31: Tóc bạc, vợ chê già, mùi – ngứa vùng kín, đồ lót, tài xế ngồi nhiều | D31: • Tóc bạc trắng, vợ chê già? • Ngứa, mùi vùng kín đàn ông do đâu? • Mặc quần lót chật ảnh hưởng gì? | E31: 18. Quần boxer nam thông hơi Natural Breath (combo 3) 16. Dầu gội phủ bạc Nezha 400ml 17. Dầu gội phủ bạc thảo dược Kim Thảo (nâu coffee) 6. Bọt vệ sinh nam Oniiz (combo) | F31: =LO_TRINH!G15
A32: T5 | B32: Sống khỏe tuổi 50+ | C32: Mỏi lưng, cổ vai gáy, móng chân, quà cho vợ, quà Tết cho ba | D32: • Mỏi lưng mùa lạnh làm sao cho đỡ? • Móng chân dày, quặp cắt sao khỏi đau? • Quà Tết cho ba: đừng mua rượu | E32: 20. Gối massage hồng ngoại Kingtech KP-315 19. Đai lưng tự nóng Kazumi 21. Máy massage cầm tay mini 22. Kềm cắt móng Kềm Nghĩa M.401 | F32: =LO_TRINH!H15
E33: Tổng | F33: =SUM(F28:F32)

Sheet LO_TRINH
A1: LỘ TRÌNH 12 TUẦN – VIDEO/NGÀY THEO TRỤ CỘT
A2: Ô xanh dương = số video/ngày của từng trụ cột, chỉnh được. THEO_DOI_NGAY, DU_BAO, KENH tự lấy số từ bảng này.
A3: Tuần | B3: Từ ngày | C3: Đến ngày | D3: T1 | E3: T2 | F3: T3 | G3: T4 | H3: T5 | I3: Tổng/ngày | J3: Tổng/tuần | K3: Mốc / sự kiện
A4: 1 | B4: 46314 | C4: =B4+6 | D4: 2 | E4: 1 | F4: 1 | G4: 1 | H4: 0 | I4: =SUM(D4:H4) | J4: =I4*7 | K4: Chạy lại nhịp đăng bằng Postiz · 20/10 Ngày Phụ nữ VN: quà cho vợ
A5: 2 | B5: 46321 | C5: =B5+6 | D5: 2 | E5: 1 | F5: 1 | G5: 1 | H5: 1 | I5: =SUM(D5:H5) | J5: =I5*7 | K5: Đo giữ chân 3 giây và click theo trụ cột
A6: 3 | B6: 46328 | C6: =B6+6 | D6: 3 | E6: 1 | F6: 1 | G6: 1 | H6: 1 | I6: =SUM(D6:H6) | J6: =I6*7 | K6: Kịch bản sale 11.11
A7: 4 | B7: 46335 | C7: =B7+6 | D7: 3 | E7: 2 | F7: 1 | G7: 1 | H7: 1 | I7: =SUM(D7:H7) | J7: =I7*7 | K7: 11.11 (thứ Tư) · ĐỦ 8 video/ngày
A8: 5 | B8: 46342 | C8: =B8+6 | D8: 3 | E8: 2 | F8: 1 | G8: 1 | H8: 1 | I8: =SUM(D8:H8) | J8: =I8*7 | K8: 19/11 Ngày Quốc tế Nam giới · review tháng 1
A9: 6 | B9: 46349 | C9: =B9+6 | D9: 3 | E9: 2 | F9: 1 | G9: 1 | H9: 1 | I9: =SUM(D9:H9) | J9: =I9*7 | K9: Black Friday 27/11: sản phẩm giá cao
A10: 7 | B10: 46356 | C10: =B10+6 | D10: 3 | E10: 2 | F10: 1 | G10: 1 | H10: 1 | I10: =SUM(D10:H10) | J10: =I10*7 | K10: Trời lạnh: tiểu đêm, đau khớp tăng
A11: 8 | B11: 46363 | C11: =B11+6 | D11: 3 | E11: 2 | F11: 1 | G11: 1 | H11: 1 | I11: =SUM(D11:H11) | J11: =I11*7 | K11: 12.12 (thứ Bảy)
A12: 9 | B12: 46370 | C12: =B12+6 | D12: 3 | E12: 2 | F12: 1 | G12: 1 | H12: 1 | I12: =SUM(D12:H12) | J12: =I12*7 | K12: Tất niên, nhậu nhiều: kẽm, bổ thận
A13: 10 | B13: 46377 | C13: =B13+6 | D13: 3 | E13: 2 | F13: 1 | G13: 1 | H13: 1 | I13: =SUM(D13:H13) | J13: =I13*7 | K13: Noel 24–25/12
A14: 11 | B14: 46384 | C14: =B14+6 | D14: 3 | E14: 2 | F14: 1 | G14: 1 | H14: 1 | I14: =SUM(D14:H14) | J14: =I14*7 | K14: Tết Dương lịch · lên kịch bản Tết
A15: 12 | B15: 46391 | C15: =B15+6 | D15: 3 | E15: 2 | F15: 1 | G15: 1 | H15: 1 | I15: =SUM(D15:H15) | J15: =I15*7 | K15: Review quý · quà Tết cho ba, phủ bạc đón Tết
A16: Tổng 12 tuần | J16: =SUM(J4:J15)
A17: T1 Phong độ & tiết niệu · T2 Chuyện vợ chồng · T3 Bệnh nền & chuyện ấy · T4 Phong độ bề ngoài · T5 Sống khỏe tuổi 50+
A19: Các giai đoạn và điều kiện qua cửa
A20: Giai đoạn | C20: Thời gian | F20: Mục tiêu | K20: Điều kiện để sang giai đoạn sau
A21: Giai đoạn 0 – Dựng nền móng | C21: 16/10 – 18/10 | F21: Link Shopee sạch kèm Sub_id, script Postiz cho page, khuôn prompt hỏi đáp gắn sản phẩm + review, đệm 2 ngày video | K21: Chạy thử trọn 1 video hỏi đáp gắn SP và 1 video review: Viral Studio → QC → Postiz → link ở bình luận gốc
A22: Giai đoạn 1 – Chạy lại nhịp đăng | C22: 19/10 – 01/11 (tuần 1–2) | F22: 5–6 video/ngày đúng giờ. Đo giữ chân 3 giây, click link, đơn theo Sub_id từng video | K22: Page không bị cảnh báo hay hạn chế · QC đạt ≥ 90% · đăng đúng lịch ≥ 90%
A23: Giai đoạn 2 – Đủ 8 video/ngày | C23: 02/11 – 15/11 (tuần 3–4) | F23: Lên 7 rồi 8 video/ngày. Chạy chiến dịch 11.11 | K23: Có đơn đầu tiên qua Sub_id · đệm video ≥ 2 ngày
A24: Giai đoạn 3 – Tối ưu | C24: 16/11 – 29/11 (tuần 5–6) | F24: Nhân bản top 3 video/tuần. Ngày Quốc tế Nam giới 19/11, Black Friday 27/11 | K24: Biết trụ cột và sản phẩm nào ra đơn; cắt sản phẩm hạng C không đơn
A25: Giai đoạn 4 – Mùa cuối năm & Tết | C25: 30/11 – 10/01 (tuần 7–12) | F25: 12.12, Noel, tất niên, chuẩn bị Tết 2027 (06/02): quà Tết cho ba, phủ bạc tóc | K25: Review quý: đủ số liệu thì cân nhắc mở kênh thứ hai cho cùng tệp (ví dụ page Ông Giang Sức Khỏe)

Sheet NHAN_SU
A1: NHÂN SỰ & PHÂN VAI
A2: Số người cần tự tính theo công suất (ô xanh dương). Điền tên người vào cột “Họ tên”.
A3: Thông số công suất
A4: Video mục tiêu/ngày (lấy từ LO_TRINH) | B4: =MAX(LO_TRINH!I4:I15)
A5: Prompt 1 biên kịch viết/ngày | B5: 15
A6: Video 1 người sản xuất/ngày | B6: 10
A7: Bài 1 người QC & đăng/ngày | B7: 40
A10: Vai trò | B10: Số người cần | C10: Họ tên (điền) | D10: Kiêm vai | E10: Trách nhiệm chính | F10: Đầu ra mỗi ngày | G10: KPI | H10: Công cụ / skill | I10: Báo cáo cho
A11: R1 · Điều phối kiêm trưởng nội dung | B11: 1 | E11: Chọn chủ đề tuần, duyệt prompt trong 4 giờ, giữ giọng Chị Giang và luật xưng hô, bảng từ cấm, quyết định nhân bản hay cắt sản phẩm | F11: Duyệt 8–12 prompt/ngày; 56 ý tưởng/tuần vào KHO_KICH_BAN | G11: Hoa hồng/tuần · giữ chân 3 giây ≥ 30% · prompt đạt ngay lần đầu ≥ 80% | H11: File vận hành này, báo cáo Shopee affiliate, FB Insights | I11: —
A12: R2 · Biên kịch – master prompt | B12: =ROUNDUP($B$4/$B$5,0) | E12: Viết master prompt theo khuôn “Chị ơi, cho em hỏi thầm” (70s/7 shot) hoặc review (50s/5 shot), trước ngày đăng 2 ngày; sản phẩm nhắc đúng 1 lần | F12: 15 prompt/người/ngày | G12: Prompt đạt duyệt/ngày · tỷ lệ phải sửa | H12: Skill master-prompt, chi-giang-loat-2/_tao-prompt-*.py, chi-giang-review-san-pham | I12: R1
A13: R3 · Sản xuất video (Viral Studio) | B13: =ROUNDUP($B$4/$B$6,0) | E13: Xếp hàng studio_create (nguyên văn master prompt + ảnh nhân vật), soát mặt nhân vật từng shot, tạo lại shot lỗi, xuất MP4 9:16, đặt tên đúng quy tắc | F13: 10 video đạt QC/người/ngày | G13: Video đạt QC/ngày · tỷ lệ phải làm lại ≤ 10% | H13: Skill viral-studio-tao-video, viral-studio-theo-doi | I13: R1
A14: R4 · Đăng bài, cộng đồng & dữ liệu | B14: =ROUNDUP($B$4/$B$7,0) | E14: QC 10 điểm, lên lịch Postiz 8 khung giờ, link kèm Sub_id ở bình luận gốc, trực bình luận/inbox, kiểm tra link thứ Hai, nhập số liệu ngày | F14: 8 bài/ngày đúng giờ, đúng link; số liệu trước 10:00 | G14: Đúng lịch 100% · 0 bài sai link · phản hồi bình luận trong 12 giờ | H14: Postiz (mlabai.uk), Shopee affiliate, Meta Business Suite, PostForge | I14: R1
A15: TỔNG NHÂN SỰ KHI ĐỦ 8 VIDEO/NGÀY | B15: =SUM(B11:B14)
A16: Gợi ý giai đoạn 1 (5–6 video/ngày): 2 người – người 1 kiêm R1 + R2 (chọn chủ đề, viết và duyệt prompt); người 2 kiêm R3 + R4 (Viral Studio, QC, đăng, bình luận, số liệu). Tăng người khi view thực tế vượt ngưỡng hòa vốn ở DU_BAO.

Sheet QUY_TRINH
A1: QUY TRÌNH VẬN HÀNH (SOP)
A2: 10 bước cho một video, từ ý tưởng đến số liệu.
A4: Bước | B4: Việc | C4: Khi nào | D4: Làm (R) | E4: Phối hợp | F4: Đầu vào | G4: Đầu ra
A5: 1 | B5: Lên kho ý tưởng tuần | C5: Chủ nhật | D5: R1 | E5: R4 | F5: Bình luận hay, báo cáo đơn theo Sub_id, top video, KaloData | G5: 56 ý tưởng trong KHO_KICH_BAN (trạng thái “Ý tưởng”), đủ 5 trụ cột
A6: 2 | B6: Viết master prompt | C6: Trước ngày đăng 2 ngày | D6: R2 | E6: R1 | F6: Ý tưởng + khuôn hỏi đáp hoặc review + ảnh nhân vật | G6: File prompt .md, trạng thái “Chờ duyệt”
A7: 3 | B7: Duyệt prompt | C7: Trong 4 giờ | D7: R1 | E7: R2 | F7: Prompt chờ duyệt + bảng từ cấm | G7: “Đã duyệt” hoặc “Cần sửa” kèm góp ý
A8: 4 | B8: Xếp hàng Viral Studio | C8: Trước ngày đăng 1 ngày | D8: R3 | E8: R1 | F8: Prompt đã duyệt, nhan-vat-chi.png | G8: studio_create; trạng thái “Đang sản xuất”
A9: 5 | B9: Soát shot & xuất video | C9: Trong ngày | D9: R3 | E9: R4 | F9: Video Viral Studio | G9: Làm lại shot lỗi; MP4 1080×1920, trạng thái “QC”
A10: 6 | B10: Kiểm tra chất lượng (QC) | C10: Trong ngày sản xuất | D10: R4 | E10: R1 | F10: Video + checklist 10 điểm | G10: Đạt → “Sẵn sàng đăng”; lỗi → trả R3
A11: 7 | B11: Lên lịch đăng | C11: Trước 17:00 ngày trước | D11: R4 | E11: R1 | F11: Video sẵn sàng + link kèm Sub_id (cột I của KHO_KICH_BAN) | G11: Postiz: Reel + link ở bình luận gốc, trạng thái “Đã đăng”
A12: 8 | B12: Trực bình luận, inbox | C12: 10:00 và 21:00 | D12: R4 | E12: R1 | F12: Bài đã đăng | G12: Ghim link, trả lời, ẩn bình luận tục, gom câu hỏi
A13: 9 | B13: Nhập số liệu | C13: Mỗi ngày trước 10:00 | D13: R4 | E13: R1 | F13: Shopee affiliate (lọc theo Sub_id) + FB Insights | G13: THEO_DOI_NGAY và cột View/Click/Đơn của KHO_KICH_BAN
A14: 10 | B14: Review tuần | C14: Chủ nhật 19:00 | D14: R1 | E14: Cả team | F14: TONG_QUAN, top 3 video, đơn theo Sub_id | G14: 5 biến thể cho mỗi top video; danh sách cắt/nhân sản phẩm
A16: Ma trận trách nhiệm RACI (R = làm, A = chịu trách nhiệm cuối, C = tham vấn, I = được báo)
A17: Bước | B17: Việc | C17: R1 | D17: R2 | E17: R3 | F17: R4
A18: 1 | B18: Lên kho ý tưởng tuần | C18: A | D18: C | F18: C
A19: 2 | B19: Viết master prompt | C19: A | D19: R
A20: 3 | B20: Duyệt prompt | C20: R | D20: I
A21: 4 | B21: Xếp hàng Viral Studio | C21: I | E21: R
A22: 5 | B22: Soát shot & xuất video | C22: A | E22: R | F22: I
A23: 6 | B23: Kiểm tra chất lượng (QC) | C23: A | E23: I | F23: R
A24: 7 | B24: Lên lịch đăng | C24: I | F24: R
A25: 8 | B25: Trực bình luận, inbox | C25: I | F25: R
A26: 9 | B26: Nhập số liệu | C26: I | F26: R
A27: 10 | B27: Review tuần | C27: A | D27: C | E27: C | F27: R
B28: R1 Điều phối kiêm trưởng nội dung · R2 Biên kịch – master prompt · R3 Sản xuất video (Viral Studio) · R4 Đăng bài, cộng đồng & dữ liệu
A30: Checklist QC 10 điểm (đạt hết mới được đăng)
A31: # | B31: Tiêu chí
A32: 1 | B32: Hook 3 giây: câu hỏi nóng, băng chữ đỏ ghi đúng câu hỏi
A33: 2 | B33: Gương mặt Chị Giang đúng ảnh chuẩn, đồng nhất mọi shot; trang phục đúng
A34: 3 | B34: Không xưng hay được gọi bác sĩ, dược sĩ, chuyên gia; không áo blouse, ống nghe
A35: 4 | B35: Không tục, không tả hành vi chi tiết, không hình gợi dục (kể cả ảnh bìa)
A36: 5 | B36: Không cam kết y tế: không “chữa”, “trị dứt”, “tăng sinh lý”; thực phẩm chức năng có câu “không phải là thuốc”
A37: 6 | B37: Sản phẩm nhắc đúng 1 lần (video hỏi đáp), đúng sản phẩm của link sẽ gắn
A38: 7 | B38: Giọng miền Nam, gọi “anh”, “mấy anh”; nhịp chậm, rõ
A39: 8 | B39: Tiếng rõ, khớp miệng, không đứt giữa các shot; chữ không sai chính tả
A40: 9 | B40: Đúng 1080×1920, đúng thời lượng (70s hỏi đáp, 50s review), không đen hình đầu/cuối
A41: 10 | B41: Bối cảnh khác video hôm trước (không lặp khuôn); tên file đúng quy tắc
A43: Nhịp làm việc một ngày
A44: Giờ | B44: Việc | D44: Ai | F44: Ghi chú
...

Sheet LICH_DANG
A1: LỊCH ĐĂNG – 8 KHUNG GIỜ/NGÀY
A2: Giờ theo thói quen lướt Facebook của đàn ông 45+: cà phê sáng, nghỉ trưa, tối muộn. Tuần 1–3 chưa đủ 8 video thì bỏ bớt khung 13:00 và 22:45 trước.
A4: Khung giờ | B4: Loại video | C4: Mục tiêu | D4: Gắn sản phẩm
A5: 05:45 | B5: Hỏi đáp (không sản phẩm) | C5: Kéo view giờ cà phê sáng | D5: Không
A6: 07:30 | B6: Review sản phẩm – hạng A | C6: Ra đơn | D6: Có (1 sản phẩm)
A7: 11:30 | B7: Hỏi đáp gắn SP – T3 bệnh nền | C7: Ra đơn giờ nghỉ trưa | D7: Có (nhắc 1 lần)
A8: 13:00 | B8: Tình huống vợ chồng | C8: Bình luận, chia sẻ | D8: Tùy tập
A9: 17:30 | B9: Hỏi đáp gắn SP – T1 phong độ | C9: Ra đơn giờ tan làm | D9: Có (nhắc 1 lần)
A10: 20:00 | B10: Review sản phẩm – hạng A khác buổi sáng | C10: Ra đơn giờ vàng | D10: Có (1 sản phẩm)
A11: 21:30 | B11: Hỏi đáp gắn SP – T2 chuyện vợ chồng | C11: Giờ vàng chủ đề nhạy cảm | D11: Có (nhắc 1 lần)
A12: 22:45 | B12: Hỏi đáp (không sản phẩm) | C12: Giữ lượt tiếp cận cuối ngày | D12: Không
A14: Chủ đề theo thứ trong tuần
A15: Thứ | B15: Chủ đề ngày | C15: Bối cảnh gợi ý | D15: Sản phẩm tập trung
A16: Thứ 2 | B16: Sai lầm đàn ông hay mắc | C16: Quán cà phê cóc vỉa hè | D16: Kẽm DSD / Kẽm ADA
A17: Thứ 3 | B17: Hiểu vợ (T2) | C17: Phòng khách buổi tối | D17: Gối massage (chồng tặng vợ) / Oniiz
A18: Thứ 4 | B18: Bệnh nền & chuyện ấy (T3) | C18: Bàn làm việc, hộp thuốc | D18: Máy đo Omron / đai lưng tự nóng
A19: Thứ 5 | B19: Tiểu đêm, thận, tiền liệt tuyến (T1) | C19: Phòng ngủ đèn vàng | D19: Botamax / Vương Bảo
A20: Thứ 6 | B20: Phong độ bề ngoài (T4) | C20: Tiệm hớt tóc, phòng tắm | D20: Quần boxer thông hơi / phủ bạc Nezha
A21: Thứ 7 | B21: Tình huống vợ chồng cuối tuần | C21: Bữa cơm gia đình, quán nhậu | D21: Combo 2 sản phẩm
A22: Chủ nhật | B22: Hỏi đáp từ bình luận | C22: Quán cà phê sân vườn | D22: Sản phẩm bán tốt nhất tuần
A24: Lịch mùa vụ 10/2026 – 01/2027
A25: Thời điểm | B25: Sự kiện | C25: Hướng nội dung
A26: 20/10 | B26: Ngày Phụ nữ Việt Nam | C26: “Tặng vợ tuổi 50 cái gì”: gối massage hồng ngoại, trà sâm tố nữ
A27: Tháng 10–12 | B27: Trời trở lạnh | C27: Tiểu đêm tăng, đau khớp: Botamax, đai lưng tự nóng, gối massage
A28: 10–11/11 | B28: Sale 11.11 | C28: 3 ngày trước sale: tăng review lên 3/8 video; máy đo Omron, gối massage (giá cao)
A29: 19/11 | B29: Ngày Quốc tế Nam giới | C29: Tuần sức khỏe đàn ông: Botamax, kẽm, tiền liệt tuyến, tầm soát
A30: 27/11 | B30: Black Friday | C30: Sản phẩm giá cao: máy đo Omron, gối massage hồng ngoại, combo quần boxer
A31: 12/12 | B31: Sale 12.12 (thứ Bảy) | C31: Như 11.11; thêm combo quà cho ba
A32: Cuối năm | B32: Tất niên, nhậu nhiều | C32: “Rượu bia và chuyện ấy”: kẽm, Botamax
A33: 24–25/12 | B33: Noel | C33: Tình huống vợ chồng: quà cuối năm cho nhau
A34: Tháng 1/2027 | B34: Chuẩn bị Tết 2027 (Tết 06/02) | C34: Quà Tết cho ba (máy đo Omron, gối massage), phủ bạc Nezha đón Tết
A36: Quy tắc chống lặp
A37: • | B37: Một sản phẩm tối đa 2 lần/ngày, mỗi lần đổi bối cảnh và góc kể
A38: • | B38: Không dùng chung câu mở đầu quá 3 lần/tuần; băng chữ đỏ mỗi video một câu hỏi khác
A39: • | B39: Biến thể của video thắng cách nhau ≥ 5 ngày
A40: • | B40: Postiz giới hạn ~30 request/giờ: 8 bài × 2 request, script tự chờ

Sheet SAN_PHAM
A1: SẢN PHẨM AFFILIATE SHOPEE – 22 LINK
A2: Tham chiếu duy nhất: sản phẩm trong link Shopee (tên, giá, hoa hồng). Hạng xếp theo hoa hồng/đơn trên Shopee và độ hợp chủ đề. Link kèm Sub_id ở cột M là link chung; link riêng từng video nằm ở KHO_KICH_BAN cột I.
A4: Mã SP | B4: Nhóm | C4: Tên sản phẩm (theo link Shopee) | D4: Tên đầy đủ trên Shopee | E4: Giá (đ) | F4: HH % | G4: HH/đơn (đ) | H4: Trụ cột chính | I4: Trụ cột phụ | J4: Hạng | K4: Góc nội dung | L4: Link Shopee Affiliate | M4: Link kèm Sub_id (chung) | N4: Thư mục ảnh | O4: Số ảnh | P4: Ghi chú | Q4: Trạng thái link | R4: Video trong kho | S4: Đơn ghi nhận
A5: 1 | B5: 1. Sinh lý & tiết niệu | C5: Kẽm DSD Multi Ginseng B+ Plus 150mg (60 viên) | D5: Viên Uống Kẽm DSD Multi Ginseng B+ Plus 150mg Hộp 60 Viên - Vitamin B & Nhân Sâm - Bổ Sung Kẽm, Tăng Cường Sức Khỏe | E5: 175750 | F5: 0.075 | G5: =E5*F5 | H5: T1 | J5: B | K5: Đàn ông nhậu nhiều, ra mồ hôi nhiều dễ hụt kẽm: hay mệt, rụng tóc, ra ít | L5: https://s.shopee.vn/4fx1tDnhTe | M5: https://s.shopee.vn/4fx1tDnhTe?sub_id=ChiGiang-Chung-FBReels-SP01 | N5: D:\video-ai-aff\shopee-aff-crawler\storage\images\4fx1tDnhTe | O5: 6 | Q5: Chưa kiểm tra | R5: =COUNTIF(KHO_KICH_BAN!$G$5:$G$404,A5) | S5: =SUMIF(KHO_KICH_BAN!$G$5:$G$404,A5,KHO_KICH_BAN!$S$5:$S$404)
A6: 2 | B6: 1. Sinh lý & tiết niệu | C6: Viên Bổ Thận DSD Sâm Nhung | D6: TPBVSK Viên Bổ Thận DSD Sâm Nhung Bổ Thận hỗ trợ bổ huyết, dưỡng thận, cải thiện đau lưng mỏi gối. Hộp 1 lọ x 60 viên | E6: 215000 | F6: 0.175 | G6: =E6*F6 | H6: T1 | I6: T5 | J6: A | K6: Đêm tiểu nhiều, sáng lưng mỏi nhừ, chiều về hết hứng | L6: https://s.shopee.vn/5AtIVGl1EU | M6: https://s.shopee.vn/5AtIVGl1EU?sub_id=ChiGiang-Chung-FBReels-SP02 | N6: D:\video-ai-aff\shopee-aff-crawler\storage\images\5AtIVGl1EU | O6: 5 | P6: Đợt đầu crawl nhầm “Sâm Nhung Bổ Thận New” 35k – đã crawl lại đúng hàng DSD | Q6: Chưa kiểm tra | R6: =COUNTIF(KHO_KICH_BAN!$G$5:$G$404,A6) | S6: =SUMIF(KHO_KICH_BAN!$G$5:$G$404,A6,KHO_KICH_BAN!$S$5:$S$404)
A7: 3 | B7: 1. Sinh lý & tiết niệu | C7: Vương Bảo Thái Minh (tiền liệt tuyến) | D7: Vương Bảo Thái Minh - Viên uống hỗ trợ giảm kích thước tuyến tiền liệt ở nam giới - Hộp 20 viên - lọ 80 viên | E7: 275000 | F7: 0.025 | G7: =E7*F7 | H7: T1 | J7: C | K7: Đêm dậy tiểu 3–4 lần, tiểu xong còn nhỏ giọt | L7: https://s.shopee.vn/gQt7yIJF2 | M7: https://s.shopee.vn/gQt7yIJF2?sub_id=ChiGiang-Chung-FBReels-SP03 | N7: D:\video-ai-aff\shopee-aff-crawler\storage\images\gQt7yIJF2 | O7: 6 | Q7: Chưa kiểm tra | R7: =COUNTIF(KHO_KICH_BAN!$G$5:$G$404,A7) | S7: =SUMIF(KHO_KICH_BAN!$G$5:$G$404,A7,KHO_KICH_BAN!$S$5:$S$404)
A8: 4 | B8: 1. Sinh lý & tiết niệu | C8: Viên Thận Botamax | D8: Viên Thận BOTAMAX - Hỗ trợ bổ thận, cải thiện chức năng thận, giảm đau lưng, mỏi gối, tiểu nhiều lần - Lọ 60/90 Viên | E8: 265000 | F8: 0.175 | G8: =E8*F8 | H8: T1 | J8: A | K8: Thận yếu có phải yếu sinh lý? – lưng mỏi, tiểu đêm | L8: https://s.shopee.vn/Lo2jOzo00 | M8: https://s.shopee.vn/Lo2jOzo00?sub_id=ChiGiang-Chung-FBReels-SP04 | N8: D:\video-ai-aff\shopee-aff-crawler\storage\images\Lo2jOzo00 | O8: 6 | Q8: Chưa kiểm tra | R8: =COUNTIF(KHO_KICH_BAN!$G$5:$G$404,A8) | S8: =SUMIF(KHO_KICH_BAN!$G$5:$G$404,A8,KHO_KICH_BAN!$S$5:$S$404)
A9: 5 | B9: 1. Sinh lý & tiết niệu | C9: Kẽm ADA 150mg | D9: Kẽm ADA 150mg Kẽm Gluconate Nguyên Liệu Nhập Pháp. - Hỗ trợ tăng cường sức khỏe, đề kháng | E9: 67000 | F9: 0.175 | G9: =E9*F9 | H9: T1 | J9: B | K9: Kẽm uống lúc nào cho đúng, uống bao lâu mới thấy khác | L9: https://s.shopee.vn/6AlpgAUH53 | M9: https://s.shopee.vn/6AlpgAUH53?sub_id=ChiGiang-Chung-FBReels-SP05 | N9: D:\video-ai-aff\shopee-aff-crawler\storage\images\6AlpgAUH53 | O9: 5 | Q9: Chưa kiểm tra | R9: =COUNTIF(KHO_KICH_BAN!$G$5:$G$404,A9) | S9: =SUMIF(KHO_KICH_BAN!$G$5:$G$404,A9,KHO_KICH_BAN!$S$5:$S$404)
A10: 6 | B10: 1. Sinh lý & tiết niệu | C10: Bọt vệ sinh nam Oniiz (combo) | D10: Bộ 6 Bọt vệ sinh nam Oniiz, Combo 3 Bọt vệ sinh, Dung dịch Masculine Foam Plus hương nước hoa, cocktail 100ml và 145ml | E10: 259000 | F10: 0.045 | G10: =E10*F10 | H10: T4 | I10: T2 | J10: B | K10: Ngứa, mùi, mồ hôi vùng kín; vệ sinh trước khi gần vợ | L10: https://s.shopee.vn/6fi6I4Q0Hu | M10: https://s.shopee.vn/6fi6I4Q0Hu?sub_id=ChiGiang-Chung-FBReels-SP06 | N10: D:\video-ai-aff\shopee-aff-crawler\storage\images\6fi6I4Q0Hu | O10: 3 | Q10: Chưa kiểm tra | R10: =COUNTIF(KHO_KICH_BAN!$G$5:$G$404,A10) | S10: =SUMIF(KHO_KICH_BAN!$G$5:$G$404,A10,KHO_KICH_BAN!$S$5:$S$404)
A11: 8 | B11: 1. Sinh lý & tiết niệu | C11: Bao cao su Durex Performa | D11: Bao Cao Su Durex PERFORMA ,Kéo Dài Thời Gian, Siêu Mỏng, Nhiều Gel - Hộp 12 chiếc | E11: 20000 | F11: 0.135 | G11: =E11*F11 | H11: T2 | J11: C | K11: Vợ chồng lớn tuổi có cần dùng bao không | L11: https://s.shopee.vn/7VHDHhq6DU | M11: https://s.shopee.vn/7VHDHhq6DU?sub_id=ChiGiang-Chung-FBReels-SP08 | N11: D:\video-ai-aff\shopee-aff-crawler\storage\images\7VHDHhq6DU | O11: 6 | P11: Giá trên link là phân loại nhỏ nhất – kiểm tra giá hộp 12 trước khi làm video | Q11: Chưa kiểm tra | R11: =COUNTIF(KHO_KICH_BAN!$G$5:$G$404,A11) | S11: =SUMIF(KHO_KICH_BAN!$G$5:$G$404,A11,KHO_KICH_BAN!$S$5:$S$404)
A12: 9 | B12: 2. Bệnh nền | C12: Gel xoa bóp xương khớp Phục Thể An (Musecos) | D12: [LOẠI 1] Gel Xoa Bóp Xương Khớp Musecos Phục Thể An - Giảm Đau Nhức Vai Gáy, Tê Mỏi Tay Chân, Thẩm Thấu Nhanh (Tuýp 50g) | E12: 24402 | F12: 0.025 | G12: =E12*F12 | H12: T3 | I12: T5 | J12: C | K12: Đau lưng, mỏi gối mùa lạnh – thoa tại chỗ | L12: https://s.shopee.vn/3Vl4VSZVgM | M12: https://s.shopee.vn/3Vl4VSZVgM?sub_id=ChiGiang-Chung-FBReels-SP09 | N12: D:\video-ai-aff\shopee-aff-crawler\storage\images\3Vl4VSZVgM | O12: 4 | P12: Giá trên link là phân loại nhỏ nhất | Q12: Chưa kiểm tra | R12: =COUNTIF(KHO_KICH_BAN!$G$5:$G$404,A12) | S12: =SUMIF(KHO_KICH_BAN!$G$5:$G$404,A12,KHO_KICH_BAN!$S$5:$S$404)
A13: 10 | B13: 2. Bệnh nền | C13: Linh Chi Thiên Ma Thấu Cốt Hoàn | D13: Linh Chi Thiên Ma Thấu Cốt Hoàn | E13: 78000 | F13: 0.025 | G13: =E13*F13 | H13: T3 | J13: C | K13: Đau khớp gối khi trời trở lạnh | L13: https://s.shopee.vn/4B0lIkf37r | M13: https://s.shopee.vn/4B0lIkf37r?sub_id=ChiGiang-Chung-FBReels-SP10 | N13: D:\video-ai-aff\shopee-aff-crawler\storage\images\4B0lIkf37r | O13: 4 | Q13: Chưa kiểm tra | R13: =COUNTIF(KHO_KICH_BAN!$G$5:$G$404,A13) | S13: =SUMIF(KHO_KICH_BAN!$G$5:$G$404,A13,KHO_KICH_BAN!$S$5:$S$404)
A14: 11 | B14: 2. Bệnh nền | C14: Máy đo huyết áp Omron HEM-7180 | D14: Máy Đo Huyết Áp Bắp Tay Tự Động Omron Ez Lite HEM-7180 |Thương Hiệu Nhật Bản, Bảo Hành 5 Năm | E14: 932000 | F14: 0.045 | G14: =E14*F14 | H14: T3 | I14: T5 | J14: A | K14: Uống thuốc huyết áp có làm yếu chuyện ấy? – tự đo ở nhà; quà Tết cho ba | L14: https://s.shopee.vn/W7Sw3QIXS | M14: https://s.shopee.vn/W7Sw3QIXS?sub_id=ChiGiang-Chung-FBReels-SP11 | N14: D:\video-ai-aff\shopee-aff-crawler\storage\images\W7Sw3QIXS | O14: 5 | Q14: Chưa kiểm tra | R14: =COUNTIF(KHO_KICH_BAN!$G$5:$G$404,A14) | S14: =SUMIF(KHO_KICH_BAN!$G$5:$G$404,A14,KHO_KICH_BAN!$S$5:$S$404)
A15: 12 | B15: 2. Bệnh nền | C15: Máy đo huyết áp AICARE X1 có giọng nói | D15: Máy Đo Huyết Áp Bắp Tay Tự Động Chính Hãng AICARE X1, Giọng Nói Tiếng Việt Dễ Sử Dụng Tại Nhà | E15: 289000 | F15: 0.025 | G15: =E15*F15 | H15: T3 | I15: T5 | J15: C | K15: Ba mẹ mắt kém tự đo, máy đọc to kết quả | L15: https://s.shopee.vn/9KirSKa8Oy | M15: https://s.shopee.vn/9KirSKa8Oy?sub_id=ChiGiang-Chung-FBReels-SP12 | N15: D:\video-ai-aff\shopee-aff-crawler\storage\images\9KirSKa8Oy | O15: 5 | P15: Rẻ hơn Omron nhưng hoa hồng 2,5% | Q15: Chưa kiểm tra | R15: =COUNTIF(KHO_KICH_BAN!$G$5:$G$404,A15) | S15: =SUMIF(KHO_KICH_BAN!$G$5:$G$404,A15,KHO_KICH_BAN!$S$5:$S$404)
A16: 13 | B16: 2. Bệnh nền | C16: Viên dây thìa canh Diabetna (tiểu đường) | D16: Viên uống dây thìa canh Diabetna Ích Nhân dành cho người tiểu đường - giúp làm giảm đường huyết biến chứng hộp 120V | E16: 31000 | F16: 0.115 | G16: =E16*F16 | H16: T3 | J16: C | K16: Tiểu đường và chuyện ấy | L16: https://s.shopee.vn/3LReJLo8Kh | M16: https://s.shopee.vn/3LReJLo8Kh?sub_id=ChiGiang-Chung-FBReels-SP13 | N16: D:\video-ai-aff\shopee-aff-crawler\storage\images\3LReJLo8Kh | O16: 5 | Q16: Chưa kiểm tra | R16: =COUNTIF(KHO_KICH_BAN!$G$5:$G$404,A16) | S16: =SUMIF(KHO_KICH_BAN!$G$5:$G$404,A16,KHO_KICH_BAN!$S$5:$S$404)
A17: 14 | B17: 2. Bệnh nền | C17: Miếng dán chân Ông Lão Bắc Kinh | D17: Miếng Dán Chân Thải Độc Ông Lão Bắc Kinh Hộp, Giúp Ngủ Ngon Giảm Nhức Mỏi Thải Độc Chân Thanh Lọc Độc Tố Cơ Thể YDPharma | E17: 19900 | F17: 0.115 | G17: =E17*F17 | H17: T3 | I17: T5 | J17: C | K17: 2 giờ sáng vẫn nằm đếm quạt trần | L17: https://s.shopee.vn/2VsXJrtSkF | M17: https://s.shopee.vn/2VsXJrtSkF?sub_id=ChiGiang-Chung-FBReels-SP14 | N17: D:\video-ai-aff\shopee-aff-crawler\storage\images\2VsXJrtSkF | O17: 5 | Q17: Chưa kiểm tra | R17: =COUNTIF(KHO_KICH_BAN!$G$5:$G$404,A17) | S17: =SUMIF(KHO_KICH_BAN!$G$5:$G$404,A17,KHO_KICH_BAN!$S$5:$S$404)
A18: 15 | B18: 2. Bệnh nền | C18: Viên magie hữu cơ + B6 | D18: Viên Uống Bổ Sung Magie Hữu Cơ - Vitamin B6 - TPBVSK Giúp Giảm Căng Thẳng, Lo Âu, Chuột Rút, Đau Mỏi Cơ, Hỗ Trợ Giấc Ngủ | E18: 37000 | F18: 0.095 | G18: =E18*F18 | H18: T3 | J18: C | K18: Đêm chuột rút bắp chân, ngủ không sâu | L18: https://s.shopee.vn/1BN9jSjzRA | M18: https://s.shopee.vn/1BN9jSjzRA?sub_id=ChiGiang-Chung-FBReels-SP15 | N18: D:\video-ai-aff\shopee-aff-crawler\storage\images\1BN9jSjzRA | O18: 5 | Q18: Chưa kiểm tra | R18: =COUNTIF(KHO_KICH_BAN!$G$5:$G$404,A18) | S18: =SUMIF(KHO_KICH_BAN!$G$5:$G$404,A18,KHO_KICH_BAN!$S$5:$S$404)
A19: 16 | B19: 3. Ngoại hình & tự tin | C19: Dầu gội phủ bạc Nezha 400ml | D19: Dầu gội phủ bạc Nezha 400ml chính hãng. Dầu gội nhuộm tóc ĐEN, NÂU bền màu. Dưỡng Tóc Chăm Sóc Tóc Nam Nữ | E19: 120000 | F19: 0.145 | G19: =E19*F19 | H19: T4 | I19: T5 | J19: B | K19: Tóc bạc trắng đầu, vợ chê già – gội 1 lần là đen | L19: https://s.shopee.vn/40hL6imMMV | M19: https://s.shopee.vn/40hL6imMMV?sub_id=ChiGiang-Chung-FBReels-SP16 | N19: D:\video-ai-aff\shopee-aff-crawler\storage\images\40hL6imMMV | O19: 4 | Q19: Chưa kiểm tra | R19: =COUNTIF(KHO_KICH_BAN!$G$5:$G$404,A19) | S19: =SUMIF(KHO_KICH_BAN!$G$5:$G$404,A19,KHO_KICH_BAN!$S$5:$S$404)
A20: 17 | B20: 3. Ngoại hình & tự tin | C20: Dầu gội phủ bạc thảo dược Kim Thảo (nâu coffee) | D20: Dầu gội Nhuộm tóc thảo dược Màu Nâu Coffee phủ bạc KIM THẢO chính hãng Lên màu tự nhiên, an toàn chuẩn salon tại nhà | E20: 19500 | F20: 0.185 | G20: =E20*F20 | H20: T4 | J20: C | K20: Ngại ra tiệm nhuộm: gội phủ bạc tại nhà, màu nâu tự nhiên | L20: https://s.shopee.vn/4qGS6IXjTc | M20: https://s.shopee.vn/4qGS6IXjTc?sub_id=ChiGiang-Chung-FBReels-SP17 | N20: D:\video-ai-aff\shopee-aff-crawler\storage\images\4qGS6IXjTc | O20: 5 | P20: Crawl tìm bút phủ bạc nhưng ra dầu gội Kim Thảo – vẫn hợp chủ đề | Q20: Chưa kiểm tra | R20: =COUNTIF(KHO_KICH_BAN!$G$5:$G$404,A20) | S20: =SUMIF(KHO_KICH_BAN!$G$5:$G$404,A20,KHO_KICH_BAN!$S$5:$S$404)
A21: 18 | B21: 3. Ngoại hình & tự tin | C21: Quần boxer nam thông hơi Natural Breath (combo 3) | D21: Quần boxer nam sịp đùi thông hơi thoáng mát combo 3 quần NATURAL BREATH trunk modal gỗ sồi BOXERMAN | E21: 249430 | F21: 0.17 | G21: =E21*F21 | H21: T4 | J21: A | K21: Tài xế, ngồi nhiều: vùng kín nóng bí, quần chật | L21: https://s.shopee.vn/9V2Hev1YVq | M21: https://s.shopee.vn/9V2Hev1YVq?sub_id=ChiGiang-Chung-FBReels-SP18 | N21: D:\video-ai-aff\shopee-aff-crawler\storage\images\9V2Hev1YVq | O21: 5 | Q21: Chưa kiểm tra | R21: =COUNTIF(KHO_KICH_BAN!$G$5:$G$404,A21) | S21: =SUMIF(KHO_KICH_BAN!$G$5:$G$404,A21,KHO_KICH_BAN!$S$5:$S$404)
A22: 19 | B22: 4. Đời sống | C22: Đai lưng tự nóng Kazumi | D22: Đai lưng tự nóng KAZUMI hỗ trợ cột sống giảm đau mỏi và hỗ trợ thoát vị đĩa đệm hiệu quả - Bản POR | E22: 202000 | F22: 0.105 | G22: =E22*F22 | H22: T3 | I22: T5 | J22: A | K22: Đau lưng, thoát vị, mỏi lưng mùa lạnh | L22: https://s.shopee.vn/113jXLfZSC | M22: https://s.shopee.vn/113jXLfZSC?sub_id=ChiGiang-Chung-FBReels-SP19 | N22: D:\video-ai-aff\shopee-aff-crawler\storage\images\113jXLfZSC | O22: 4 | Q22: Chưa kiểm tra | R22: =COUNTIF(KHO_KICH_BAN!$G$5:$G$404,A22) | S22: =SUMIF(KHO_KICH_BAN!$G$5:$G$404,A22,KHO_KICH_BAN!$S$5:$S$404)
A23: 20 | B23: 4. Đời sống | C23: Gối massage hồng ngoại Kingtech KP-315 | D23: Gối Massage Nhiệt Hồng Ngoại Cao Cấp KINGTECH KP-315 - 4 Bóng Xoay - Chuyên Sâu Cổ Vai Gáy, Thắt Lưng - Chính Hãng | E23: 675540 | F23: 0.045 | G23: =E23*F23 | H23: T5 | I23: T2 | J23: A | K23: Cổ vai gáy cứng đơ; quà cho ba, chồng tặng vợ | L23: https://s.shopee.vn/1LgZw0Yxv6 | M23: https://s.shopee.vn/1LgZw0Yxv6?sub_id=ChiGiang-Chung-FBReels-SP20 | N23: D:\video-ai-aff\shopee-aff-crawler\storage\images\1LgZw0Yxv6 | O23: 5 | Q23: Chưa kiểm tra | R23: =COUNTIF(KHO_KICH_BAN!$G$5:$G$404,A23) | S23: =SUMIF(KHO_KICH_BAN!$G$5:$G$404,A23,KHO_KICH_BAN!$S$5:$S$404)
A24: 21 | B24: 4. Đời sống | C24: Máy massage cầm tay mini | D24: Máy Massage Cầm Tay Mini, Súng Massage Cầm Tay Mini Toàn Thân 6 Cấp Độ Chuyên Sâu Đa Năng - HKDOTI | E24: 120000 | F24: 0.025 | G24: =E24*F24 | H24: T5 | I24: T2 | J24: C | K24: Chồng massage cho vợ – quà 20/10 | L24: https://s.shopee.vn/2gBxWVFPSZ | M24: https://s.shopee.vn/2gBxWVFPSZ?sub_id=ChiGiang-Chung-FBReels-SP21 | N24: D:\video-ai-aff\shopee-aff-crawler\storage\images\2gBxWVFPSZ | O24: 5 | Q24: Chưa kiểm tra | R24: =COUNTIF(KHO_KICH_BAN!$G$5:$G$404,A24) | S24: =SUMIF(KHO_KICH_BAN!$G$5:$G$404,A24,KHO_KICH_BAN!$S$5:$S$404)
A25: 22 | B25: 4. Đời sống | C25: Kềm cắt móng Kềm Nghĩa M.401 | D25: Kềm Nghĩa Kềm Cắt Móng M.401 Thiết Kế Lưỡi Kềm Mỏ Vịt Hỗ Trợ Cắt Móng Quặp và Tay Cầm Mạ Mờ | E25: 88000 | F25: 0.025 | G25: =E25*F25 | H25: T5 | J25: C | K25: Móng chân dày, quặp, cắt không nổi | L25: https://s.shopee.vn/AUuoqwSmIs | M25: https://s.shopee.vn/AUuoqwSmIs?sub_id=ChiGiang-Chung-FBReels-SP22 | N25: D:\video-ai-aff\shopee-aff-crawler\storage\images\AUuoqwSmIs | O25: 4 | Q25: Chưa kiểm tra | R25: =COUNTIF(KHO_KICH_BAN!$G$5:$G$404,A25) | S25: =SUMIF(KHO_KICH_BAN!$G$5:$G$404,A25,KHO_KICH_BAN!$S$5:$S$404)
A26: 23 | B26: 4. Đời sống | C26: Trà mâm xôi sâm tố nữ A Nam | D26: Trà Mâm Xôi 4 Vị Tiệm Trà A NAM - Sâm Tố Nữ & Lá Mâm Xôi Khô, Hỗ Trợ Bổ Huyết Điều Kinh Đẹp Da. 1 | E26: 7200 | F26: 0.125 | G26: =E26*F26 | H26: T2 | J26: C | K26: Vợ tiền mãn kinh hay cáu, bốc hỏa – chồng mua tặng vợ | L26: https://s.shopee.vn/30onvCyWAQ | M26: https://s.shopee.vn/30onvCyWAQ?sub_id=ChiGiang-Chung-FBReels-SP23 | N26: D:\video-ai-aff\shopee-aff-crawler\storage\images\30onvCyWAQ | O26: 5 | Q26: Chưa kiểm tra | R26: =COUNTIF(KHO_KICH_BAN!$G$5:$G$404,A26) | S26: =SUMIF(KHO_KICH_BAN!$G$5:$G$404,A26,KHO_KICH_BAN!$S$5:$S$404)

Sheet KHO_KICH_BAN
A1: KHO KỊCH BẢN & THEO DÕI TỪNG VIDEO
A2: Mỗi dòng = 1 video. Nhập Mã SP → tên SP, link kèm Sub_id riêng của video, thư mục ảnh tự hiện. Dán link cột I vào bình luận gốc. Dòng 5 là dòng ví dụ.
A4: ID | B4: Trụ cột | C4: Loại video | D4: Tiêu đề / câu hỏi | E4: Hook 3 giây | F4: Bối cảnh | G4: Mã SP | H4: Tên SP (tự động) | I4: Link kèm Sub_id của video (tự động) | J4: Thư mục ảnh (tự động) | K4: Biên kịch | L4: Người sản xuất | M4: Trạng thái | N4: Ngày đăng | O4: Khung giờ | P4: Link bài đăng | Q4: View | R4: Click | S4: Đơn | T4: Ghi chú
A5: T1-001 | B5: T1 | C5: Hỏi đáp gắn SP | D5: Đêm dậy tiểu 3–4 lần là bị gì? | E5: Mấy anh ngoài năm mươi, đêm dậy mấy lần? | F5: Phòng ngủ đèn vàng, 2 giờ sáng | G5: 3 | H5: =IF($G5="","",IFERROR(INDEX(SAN_PHAM!$D$5:$D$26,MATCH($G5,SAN_PHAM!$A$5:$A$26,0)),"Sai mã SP")) | I5: =IF(OR($G5="",$A5=""),"",IFERROR(INDEX(SAN_PHAM!$L$5:$L$26,MATCH($G5,SAN_PHAM!$A$5:$A$26,0))&"?sub_id=ChiGiang-"&SUBSTITUTE($A5,"-","")&"-FBReels-SP"&TEXT($G5,"00"),"")) | J5: =IF($G5="","",IFERROR(INDEX(SAN_PHAM!$N$5:$N$26,MATCH($G5,SAN_PHAM!$A$5:$A$26,0)),"")) | K5: Lan (ví dụ) | L5: Minh (ví dụ) | M5: Đã đăng | N5: 46314 | O5: 11:30 | P5: https://facebook.com/reel/… (ví dụ) | Q5: 12000 | R5: 60 | S5: 2 | T5: DÒNG VÍ DỤ – số liệu minh họa, xóa khi dùng thật
A6: T1-002 | B6: T1 | C6: Review sản phẩm | D6: Review Viên Thận Botamax: lưng mỏi, tiểu đêm | E6: Anh nào đêm dậy tiểu, sáng lưng mỏi nhừ, coi hết video này | F6: Bàn trà phòng khách | G6: 4 | H6: =IF($G6="","",IFERROR(INDEX(SAN_PHAM!$D$5:$D$26,MATCH($G6,SAN_PHAM!$A$5:$A$26,0)),"Sai mã SP")) | I6: =IF(OR($G6="",$A6=""),"",IFERROR(INDEX(SAN_PHAM!$L$5:$L$26,MATCH($G6,SAN_PHAM!$A$5:$A$26,0))&"?sub_id=ChiGiang-"&SUBSTITUTE($A6,"-","")&"-FBReels-SP"&TEXT($G6,"00"),"")) | J6: =IF($G6="","",IFERROR(INDEX(SAN_PHAM!$N$5:$N$26,MATCH($G6,SAN_PHAM!$A$5:$A$26,0)),"")) | M6: Ý tưởng
A7: T1-003 | B7: T1 | C7: Hỏi đáp gắn SP | D7: Tiểu xong còn nhỏ giọt có sao không? | E7: Kéo khóa rồi mà vẫn còn… anh có bị vậy không? | F7: Hành lang nhà, ánh sáng sáng sớm | G7: 3 | H7: =IF($G7="","",IFERROR(INDEX(SAN_PHAM!$D$5:$D$26,MATCH($G7,SAN_PHAM!$A$5:$A$26,0)),"Sai mã SP")) | I7: =IF(OR($G7="",$A7=""),"",IFERROR(INDEX(SAN_PHAM!$L$5:$L$26,MATCH($G7,SAN_PHAM!$A$5:$A$26,0))&"?sub_id=ChiGiang-"&SUBSTITUTE($A7,"-","")&"-FBReels-SP"&TEXT($G7,"00"),"")) | J7: =IF($G7="","",IFERROR(INDEX(SAN_PHAM!$N$5:$N$26,MATCH($G7,SAN_PHAM!$A$5:$A$26,0)),"")) | M7: Ý tưởng
A8: T1-004 | B8: T1 | C8: Hỏi đáp gắn SP | D8: Thận yếu có phải yếu sinh lý? | E8: Ai nói thận yếu là yếu chuyện ấy? Chị nói thiệt nè | F8: Quán cà phê cóc vỉa hè | G8: 4 | H8: =IF($G8="","",IFERROR(INDEX(SAN_PHAM!$D$5:$D$26,MATCH($G8,SAN_PHAM!$A$5:$A$26,0)),"Sai mã SP")) | I8: =IF(OR($G8="",$A8=""),"",IFERROR(INDEX(SAN_PHAM!$L$5:$L$26,MATCH($G8,SAN_PHAM!$A$5:$A$26,0))&"?sub_id=ChiGiang-"&SUBSTITUTE($A8,"-","")&"-FBReels-SP"&TEXT($G8,"00"),"")) | J8: =IF($G8="","",IFERROR(INDEX(SAN_PHAM!$N$5:$N$26,MATCH($G8,SAN_PHAM!$A$5:$A$26,0)),"")) | M8: Ý tưởng
A9: T1-005 | B9: T1 | C9: Review sản phẩm | D9: Review sâm nhung bổ thận | E9: Sáng dậy lưng mỏi nhừ, chiều về hết hứng? | F9: Phòng khách có tủ thờ | G9: 2 | H9: =IF($G9="","",IFERROR(INDEX(SAN_PHAM!$D$5:$D$26,MATCH($G9,SAN_PHAM!$A$5:$A$26,0)),"Sai mã SP")) | I9: =IF(OR($G9="",$A9=""),"",IFERROR(INDEX(SAN_PHAM!$L$5:$L$26,MATCH($G9,SAN_PHAM!$A$5:$A$26,0))&"?sub_id=ChiGiang-"&SUBSTITUTE($A9,"-","")&"-FBReels-SP"&TEXT($G9,"00"),"")) | J9: =IF($G9="","",IFERROR(INDEX(SAN_PHAM!$N$5:$N$26,MATCH($G9,SAN_PHAM!$A$5:$A$26,0)),"")) | M9: Ý tưởng
A10: T1-006 | B10: T1 | C10: Hỏi đáp gắn SP | D10: Ngoài 50 ra ít, loãng là thiếu gì? | E10: Lớn tuổi ra ít là bình thường hay thiếu chất? | F10: Ban công nhiều cây | G10: 1 | H10: =IF($G10="","",IFERROR(INDEX(SAN_PHAM!$D$5:$D$26,MATCH($G10,SAN_PHAM!$A$5:$A$26,0)),"Sai mã SP")) | I10: =IF(OR($G10="",$A10=""),"",IFERROR(INDEX(SAN_PHAM!$L$5:$L$26,MATCH($G10,SAN_PHAM!$A$5:$A$26,0))&"?sub_id=ChiGiang-"&SUBSTITUTE($A10,"-","")&"-FBReels-SP"&TEXT($G10,"00"),"")) | J10: =IF($G10="","",IFERROR(INDEX(SAN_PHAM!$N$5:$N$26,MATCH($G10,SAN_PHAM!$A$5:$A$26,0)),"")) | M10: Ý tưởng
A11: T1-007 | B11: T1 | C11: Review sản phẩm | D11: Review Kẽm DSD: đàn ông nhậu nhiều dễ thiếu kẽm | E11: Ngoài 40 hay mệt, rụng tóc, ăn không ngon? | F11: Bàn nhậu sau bữa tiệc | G11: 1 | H11: =IF($G11="","",IFERROR(INDEX(SAN_PHAM!$D$5:$D$26,MATCH($G11,SAN_PHAM!$A$5:$A$26,0)),"Sai mã SP")) | I11: =IF(OR($G11="",$A11=""),"",IFERROR(INDEX(SAN_PHAM!$L$5:$L$26,MATCH($G11,SAN_PHAM!$A$5:$A$26,0))&"?sub_id=ChiGiang-"&SUBSTITUTE($A11,"-","")&"-FBReels-SP"&TEXT($G11,"00"),"")) | J11: =IF($G11="","",IFERROR(INDEX(SAN_PHAM!$N$5:$N$26,MATCH($G11,SAN_PHAM!$A$5:$A$26,0)),"")) | M11: Ý tưởng
A12: T1-008 | B12: T1 | C12: Hỏi đáp gắn SP | D12: Về hưu tự nhiên hết hứng, tại sao? | E12: Nghỉ hưu rảnh rang mà sao chuyện ấy lại nguội? | F12: Sân nhà, ghế bố | G12: 1 | H12: =IF($G12="","",IFERROR(INDEX(SAN_PHAM!$D$5:$D$26,MATCH($G12,SAN_PHAM!$A$5:$A$26,0)),"Sai mã SP")) | I12: =IF(OR($G12="",$A12=""),"",IFERROR(INDEX(SAN_PHAM!$L$5:$L$26,MATCH($G12,SAN_PHAM!$A$5:$A$26,0))&"?sub_id=ChiGiang-"&SUBSTITUTE($A12,"-","")&"-FBReels-SP"&TEXT($G12,"00"),"")) | J12: =IF($G12="","",IFERROR(INDEX(SAN_PHAM!$N$5:$N$26,MATCH($G12,SAN_PHAM!$A$5:$A$26,0)),"")) | M12: Ý tưởng
A13: T1-009 | B13: T1 | C13: Hỏi đáp | D13: Sáng thức dậy không còn “chào cờ” có đáng lo? | E13: Mấy anh để ý buổi sáng chưa? | F13: Phòng ngủ buổi sáng, rèm mở | H13: =IF($G13="","",IFERROR(INDEX(SAN_PHAM!$D$5:$D$26,MATCH($G13,SAN_PHAM!$A$5:$A$26,0)),"Sai mã SP")) | I13: =IF(OR($G13="",$A13=""),"",IFERROR(INDEX(SAN_PHAM!$L$5:$L$26,MATCH($G13,SAN_PHAM!$A$5:$A$26,0))&"?sub_id=ChiGiang-"&SUBSTITUTE($A13,"-","")&"-FBReels-SP"&TEXT($G13,"00"),"")) | J13: =IF($G13="","",IFERROR(INDEX(SAN_PHAM!$N$5:$N$26,MATCH($G13,SAN_PHAM!$A$5:$A$26,0)),"")) | M13: Ý tưởng
A14: T1-010 | B14: T1 | C14: Hỏi đáp gắn SP | D14: Rượu thuốc ngâm có bổ thật không? | E14: Bình rượu ngâm trong nhà anh có gì trong đó? | F14: Góc tủ rượu | G14: 2 | H14: =IF($G14="","",IFERROR(INDEX(SAN_PHAM!$D$5:$D$26,MATCH($G14,SAN_PHAM!$A$5:$A$26,0)),"Sai mã SP")) | I14: =IF(OR($G14="",$A14=""),"",IFERROR(INDEX(SAN_PHAM!$L$5:$L$26,MATCH($G14,SAN_PHAM!$A$5:$A$26,0))&"?sub_id=ChiGiang-"&SUBSTITUTE($A14,"-","")&"-FBReels-SP"&TEXT($G14,"00"),"")) | J14: =IF($G14="","",IFERROR(INDEX(SAN_PHAM!$N$5:$N$26,MATCH($G14,SAN_PHAM!$A$5:$A$26,0)),"")) | M14: Ý tưởng
A15: T1-011 | B15: T1 | C15: Hỏi đáp | D15: Trứng vịt lộn, hàu có tăng bản lĩnh thật không? | E15: Ăn hột vịt lộn mỗi tối có được gì? | F15: Quán ốc vỉa hè Sài Gòn | H15: =IF($G15="","",IFERROR(INDEX(SAN_PHAM!$D$5:$D$26,MATCH($G15,SAN_PHAM!$A$5:$A$26,0)),"Sai mã SP")) | I15: =IF(OR($G15="",$A15=""),"",IFERROR(INDEX(SAN_PHAM!$L$5:$L$26,MATCH($G15,SAN_PHAM!$A$5:$A$26,0))&"?sub_id=ChiGiang-"&SUBSTITUTE($A15,"-","")&"-FBReels-SP"&TEXT($G15,"00"),"")) | J15: =IF($G15="","",IFERROR(INDEX(SAN_PHAM!$N$5:$N$26,MATCH($G15,SAN_PHAM!$A$5:$A$26,0)),"")) | M15: Ý tưởng
A16: T1-012 | B16: T1 | C16: Hỏi đáp gắn SP | D16: 19/11 Quốc tế Nam giới: 3 việc đàn ông 50 nên làm | E16: Hôm nay ngày của mấy anh, chị hỏi thiệt | F16: Phòng khách trang trí nhẹ | G16: 3 | H16: =IF($G16="","",IFERROR(INDEX(SAN_PHAM!$D$5:$D$26,MATCH($G16,SAN_PHAM!$A$5:$A$26,0)),"Sai mã SP")) | I16: =IF(OR($G16="",$A16=""),"",IFERROR(INDEX(SAN_PHAM!$L$5:$L$26,MATCH($G16,SAN_PHAM!$A$5:$A$26,0))&"?sub_id=ChiGiang-"&SUBSTITUTE($A16,"-","")&"-FBReels-SP"&TEXT($G16,"00"),"")) | J16: =IF($G16="","",IFERROR(INDEX(SAN_PHAM!$N$5:$N$26,MATCH($G16,SAN_PHAM!$A$5:$A$26,0)),"")) | M16: Ý tưởng
A17: T1-013 | B17: T1 | C17: Tình huống vợ chồng | D17: Vợ hỏi: sao dạo này anh dậy đêm hoài? | E17: Anh đi đâu mà đêm nào cũng dậy vậy? | F17: Phòng ngủ, vợ ngồi dậy bật đèn | G17: 3 | H17: =IF($G17="","",IFERROR(INDEX(SAN_PHAM!$D$5:$D$26,MATCH($G17,SAN_PHAM!$A$5:$A$26,0)),"Sai mã SP")) | I17: =IF(OR($G17="",$A17=""),"",IFERROR(INDEX(SAN_PHAM!$L$5:$L$26,MATCH($G17,SAN_PHAM!$A$5:$A$26,0))&"?sub_id=ChiGiang-"&SUBSTITUTE($A17,"-","")&"-FBReels-SP"&TEXT($G17,"00"),"")) | J17: =IF($G17="","",IFERROR(INDEX(SAN_PHAM!$N$5:$N$26,MATCH($G17,SAN_PHAM!$A$5:$A$26,0)),"")) | M17: Ý tưởng
A18: T1-014 | B18: T1 | C18: Hỏi đáp gắn SP | D18: Kẽm uống lúc nào cho đúng? | E18: Uống kẽm lúc đói là sai rồi nha | F18: Bếp buổi sáng | G18: 5 | H18: =IF($G18="","",IFERROR(INDEX(SAN_PHAM!$D$5:$D$26,MATCH($G18,SAN_PHAM!$A$5:$A$26,0)),"Sai mã SP")) | I18: =IF(OR($G18="",$A18=""),"",IFERROR(INDEX(SAN_PHAM!$L$5:$L$26,MATCH($G18,SAN_PHAM!$A$5:$A$26,0))&"?sub_id=ChiGiang-"&SUBSTITUTE($A18,"-","")&"-FBReels-SP"&TEXT($G18,"00"),"")) | J18: =IF($G18="","",IFERROR(INDEX(SAN_PHAM!$N$5:$N$26,MATCH($G18,SAN_PHAM!$A$5:$A$26,0)),"")) | M18: Ý tưởng
A19: T1-015 | B19: T1 | C19: Hỏi đáp | D19: Ngoài 50 bao lâu gần vợ một lần là vừa? | E19: Câu này mấy anh hỏi chị nhiều nhất | F19: Ghế đá công viên | H19: =IF($G19="","",IFERROR(INDEX(SAN_PHAM!$D$5:$D$26,MATCH($G19,SAN_PHAM!$A$5:$A$26,0)),"Sai mã SP")) | I19: =IF(OR($G19="",$A19=""),"",IFERROR(INDEX(SAN_PHAM!$L$5:$L$26,MATCH($G19,SAN_PHAM!$A$5:$A$26,0))&"?sub_id=ChiGiang-"&SUBSTITUTE($A19,"-","")&"-FBReels-SP"&TEXT($G19,"00"),"")) | J19: =IF($G19="","",IFERROR(INDEX(SAN_PHAM!$N$5:$N$26,MATCH($G19,SAN_PHAM!$A$5:$A$26,0)),"")) | M19: Ý tưởng
A20: T2-001 | B20: T2 | C20: Hỏi đáp gắn SP | D20: Vợ mãn kinh né chồng, đừng vội nghĩ hết thương | E20: Vợ né anh có phải vì hết thương? | F20: Phòng khách buổi tối | G20: 23 | H20: =IF($G20="","",IFERROR(INDEX(SAN_PHAM!$D$5:$D$26,MATCH($G20,SAN_PHAM!$A$5:$A$26,0)),"Sai mã SP")) | I20: =IF(OR($G20="",$A20=""),"",IFERROR(INDEX(SAN_PHAM!$L$5:$L$26,MATCH($G20,SAN_PHAM!$A$5:$A$26,0))&"?sub_id=ChiGiang-"&SUBSTITUTE($A20,"-","")&"-FBReels-SP"&TEXT($G20,"00"),"")) | J20: =IF($G20="","",IFERROR(INDEX(SAN_PHAM!$N$5:$N$26,MATCH($G20,SAN_PHAM!$A$5:$A$26,0)),"")) | M20: Ý tưởng
A21: T2-002 | B21: T2 | C21: Hỏi đáp | D21: Vợ khô có phải hết thương? | E21: Câu này nhiều anh hiểu sai lắm | F21: Phòng ngủ đèn ngủ | H21: =IF($G21="","",IFERROR(INDEX(SAN_PHAM!$D$5:$D$26,MATCH($G21,SAN_PHAM!$A$5:$A$26,0)),"Sai mã SP")) | I21: =IF(OR($G21="",$A21=""),"",IFERROR(INDEX(SAN_PHAM!$L$5:$L$26,MATCH($G21,SAN_PHAM!$A$5:$A$26,0))&"?sub_id=ChiGiang-"&SUBSTITUTE($A21,"-","")&"-FBReels-SP"&TEXT($G21,"00"),"")) | J21: =IF($G21="","",IFERROR(INDEX(SAN_PHAM!$N$5:$N$26,MATCH($G21,SAN_PHAM!$A$5:$A$26,0)),"")) | M21: Ý tưởng
A22: T2-003 | B22: T2 | C22: Tình huống vợ chồng | D22: 20/10 tặng vợ tuổi 50 cái gì cho vợ vui? | E22: Hai mươi tháng mười rồi, anh mua gì cho vợ chưa? | F22: Chợ hoa, cầm bó hoa | G22: 23 | H22: =IF($G22="","",IFERROR(INDEX(SAN_PHAM!$D$5:$D$26,MATCH($G22,SAN_PHAM!$A$5:$A$26,0)),"Sai mã SP")) | I22: =IF(OR($G22="",$A22=""),"",IFERROR(INDEX(SAN_PHAM!$L$5:$L$26,MATCH($G22,SAN_PHAM!$A$5:$A$26,0))&"?sub_id=ChiGiang-"&SUBSTITUTE($A22,"-","")&"-FBReels-SP"&TEXT($G22,"00"),"")) | J22: =IF($G22="","",IFERROR(INDEX(SAN_PHAM!$N$5:$N$26,MATCH($G22,SAN_PHAM!$A$5:$A$26,0)),"")) | M22: Ý tưởng
A23: T2-004 | B23: T2 | C23: Hỏi đáp | D23: Vợ nói “em mệt” là thật hay giả? | E23: Vợ nói em mệt, anh hiểu sao? | F23: Bếp tối, vợ rửa chén | H23: =IF($G23="","",IFERROR(INDEX(SAN_PHAM!$D$5:$D$26,MATCH($G23,SAN_PHAM!$A$5:$A$26,0)),"Sai mã SP")) | I23: =IF(OR($G23="",$A23=""),"",IFERROR(INDEX(SAN_PHAM!$L$5:$L$26,MATCH($G23,SAN_PHAM!$A$5:$A$26,0))&"?sub_id=ChiGiang-"&SUBSTITUTE($A23,"-","")&"-FBReels-SP"&TEXT($G23,"00"),"")) | J23: =IF($G23="","",IFERROR(INDEX(SAN_PHAM!$N$5:$N$26,MATCH($G23,SAN_PHAM!$A$5:$A$26,0)),"")) | M23: Ý tưởng
A24: T2-005 | B24: T2 | C24: Hỏi đáp gắn SP | D24: Vợ chồng lớn tuổi có cần dùng bao? | E24: Vợ mãn kinh rồi thì khỏi cần, đúng không? | F24: Phòng khách | G24: 8 | H24: =IF($G24="","",IFERROR(INDEX(SAN_PHAM!$D$5:$D$26,MATCH($G24,SAN_PHAM!$A$5:$A$26,0)),"Sai mã SP")) | I24: =IF(OR($G24="",$A24=""),"",IFERROR(INDEX(SAN_PHAM!$L$5:$L$26,MATCH($G24,SAN_PHAM!$A$5:$A$26,0))&"?sub_id=ChiGiang-"&SUBSTITUTE($A24,"-","")&"-FBReels-SP"&TEXT($G24,"00"),"")) | J24: =IF($G24="","",IFERROR(INDEX(SAN_PHAM!$N$5:$N$26,MATCH($G24,SAN_PHAM!$A$5:$A$26,0)),"")) | M24: Ý tưởng
A25: T2-006 | B25: T2 | C25: Hỏi đáp | D25: Bao lâu không gần nhau là báo động? | E25: Một tháng, ba tháng hay một năm? | F25: Quán cà phê sân vườn | H25: =IF($G25="","",IFERROR(INDEX(SAN_PHAM!$D$5:$D$26,MATCH($G25,SAN_PHAM!$A$5:$A$26,0)),"Sai mã SP")) | I25: =IF(OR($G25="",$A25=""),"",IFERROR(INDEX(SAN_PHAM!$L$5:$L$26,MATCH($G25,SAN_PHAM!$A$5:$A$26,0))&"?sub_id=ChiGiang-"&SUBSTITUTE($A25,"-","")&"-FBReels-SP"&TEXT($G25,"00"),"")) | J25: =IF($G25="","",IFERROR(INDEX(SAN_PHAM!$N$5:$N$26,MATCH($G25,SAN_PHAM!$A$5:$A$26,0)),"")) | M25: Ý tưởng
A26: T2-007 | B26: T2 | C26: Hỏi đáp gắn SP | D26: Vệ sinh trước khi gần vợ – điều vợ ngại nói | E26: Có một chuyện vợ anh không dám nói | F26: Phòng tắm sạch sẽ, khăn treo | G26: 6 | H26: =IF($G26="","",IFERROR(INDEX(SAN_PHAM!$D$5:$D$26,MATCH($G26,SAN_PHAM!$A$5:$A$26,0)),"Sai mã SP")) | I26: =IF(OR($G26="",$A26=""),"",IFERROR(INDEX(SAN_PHAM!$L$5:$L$26,MATCH($G26,SAN_PHAM!$A$5:$A$26,0))&"?sub_id=ChiGiang-"&SUBSTITUTE($A26,"-","")&"-FBReels-SP"&TEXT($G26,"00"),"")) | J26: =IF($G26="","",IFERROR(INDEX(SAN_PHAM!$N$5:$N$26,MATCH($G26,SAN_PHAM!$A$5:$A$26,0)),"")) | M26: Ý tưởng
A27: T2-008 | B27: T2 | C27: Tình huống vợ chồng | D27: Chồng massage cho vợ, vợ cảm động | E27: Ba chục năm mới thấy ổng làm vậy | F27: Phòng khách, sofa | G27: 21 | H27: =IF($G27="","",IFERROR(INDEX(SAN_PHAM!$D$5:$D$26,MATCH($G27,SAN_PHAM!$A$5:$A$26,0)),"Sai mã SP")) | I27: =IF(OR($G27="",$A27=""),"",IFERROR(INDEX(SAN_PHAM!$L$5:$L$26,MATCH($G27,SAN_PHAM!$A$5:$A$26,0))&"?sub_id=ChiGiang-"&SUBSTITUTE($A27,"-","")&"-FBReels-SP"&TEXT($G27,"00"),"")) | J27: =IF($G27="","",IFERROR(INDEX(SAN_PHAM!$N$5:$N$26,MATCH($G27,SAN_PHAM!$A$5:$A$26,0)),"")) | M27: Ý tưởng
A28: T2-009 | B28: T2 | C28: Hỏi đáp | D28: Vì sao vợ đòi tắt đèn? | E28: Vợ đòi tắt đèn là vì ngại hay vì giận? | F28: Phòng ngủ | H28: =IF($G28="","",IFERROR(INDEX(SAN_PHAM!$D$5:$D$26,MATCH($G28,SAN_PHAM!$A$5:$A$26,0)),"Sai mã SP")) | I28: =IF(OR($G28="",$A28=""),"",IFERROR(INDEX(SAN_PHAM!$L$5:$L$26,MATCH($G28,SAN_PHAM!$A$5:$A$26,0))&"?sub_id=ChiGiang-"&SUBSTITUTE($A28,"-","")&"-FBReels-SP"&TEXT($G28,"00"),"")) | J28: =IF($G28="","",IFERROR(INDEX(SAN_PHAM!$N$5:$N$26,MATCH($G28,SAN_PHAM!$A$5:$A$26,0)),"")) | M28: Ý tưởng
A29: T2-010 | B29: T2 | C29: Hỏi đáp | D29: Vợ thích được khen điều gì nhất? | E29: Khen vợ đẹp là chưa đủ đâu mấy anh | F29: Bữa cơm gia đình | H29: =IF($G29="","",IFERROR(INDEX(SAN_PHAM!$D$5:$D$26,MATCH($G29,SAN_PHAM!$A$5:$A$26,0)),"Sai mã SP")) | I29: =IF(OR($G29="",$A29=""),"",IFERROR(INDEX(SAN_PHAM!$L$5:$L$26,MATCH($G29,SAN_PHAM!$A$5:$A$26,0))&"?sub_id=ChiGiang-"&SUBSTITUTE($A29,"-","")&"-FBReels-SP"&TEXT($G29,"00"),"")) | J29: =IF($G29="","",IFERROR(INDEX(SAN_PHAM!$N$5:$N$26,MATCH($G29,SAN_PHAM!$A$5:$A$26,0)),"")) | M29: Ý tưởng
A30: T3-001 | B30: T3 | C30: Hỏi đáp gắn SP | D30: Uống thuốc huyết áp có làm yếu chuyện ấy? | E30: Uống thuốc huyết áp xong anh thấy khác không? | F30: Bàn làm việc có hộp thuốc | G30: 11 | H30: =IF($G30="","",IFERROR(INDEX(SAN_PHAM!$D$5:$D$26,MATCH($G30,SAN_PHAM!$A$5:$A$26,0)),"Sai mã SP")) | I30: =IF(OR($G30="",$A30=""),"",IFERROR(INDEX(SAN_PHAM!$L$5:$L$26,MATCH($G30,SAN_PHAM!$A$5:$A$26,0))&"?sub_id=ChiGiang-"&SUBSTITUTE($A30,"-","")&"-FBReels-SP"&TEXT($G30,"00"),"")) | J30: =IF($G30="","",IFERROR(INDEX(SAN_PHAM!$N$5:$N$26,MATCH($G30,SAN_PHAM!$A$5:$A$26,0)),"")) | M30: Ý tưởng
A31: T3-002 | B31: T3 | C31: Review sản phẩm | D31: Review máy đo huyết áp Omron: tự đo ở nhà | E31: Đo huyết áp ở nhà mà số nhảy lung tung? | F31: Phòng khách nhà ba mẹ | G31: 11 | H31: =IF($G31="","",IFERROR(INDEX(SAN_PHAM!$D$5:$D$26,MATCH($G31,SAN_PHAM!$A$5:$A$26,0)),"Sai mã SP")) | I31: =IF(OR($G31="",$A31=""),"",IFERROR(INDEX(SAN_PHAM!$L$5:$L$26,MATCH($G31,SAN_PHAM!$A$5:$A$26,0))&"?sub_id=ChiGiang-"&SUBSTITUTE($A31,"-","")&"-FBReels-SP"&TEXT($G31,"00"),"")) | J31: =IF($G31="","",IFERROR(INDEX(SAN_PHAM!$N$5:$N$26,MATCH($G31,SAN_PHAM!$A$5:$A$26,0)),"")) | M31: Ý tưởng
A32: T3-003 | B32: T3 | C32: Hỏi đáp gắn SP | D32: Tiểu đường và chuyện ấy | E32: Đường huyết cao thì chuyện ấy ra sao? | F32: Bếp, bữa sáng | G32: 13 | H32: =IF($G32="","",IFERROR(INDEX(SAN_PHAM!$D$5:$D$26,MATCH($G32,SAN_PHAM!$A$5:$A$26,0)),"Sai mã SP")) | I32: =IF(OR($G32="",$A32=""),"",IFERROR(INDEX(SAN_PHAM!$L$5:$L$26,MATCH($G32,SAN_PHAM!$A$5:$A$26,0))&"?sub_id=ChiGiang-"&SUBSTITUTE($A32,"-","")&"-FBReels-SP"&TEXT($G32,"00"),"")) | J32: =IF($G32="","",IFERROR(INDEX(SAN_PHAM!$N$5:$N$26,MATCH($G32,SAN_PHAM!$A$5:$A$26,0)),"")) | M32: Ý tưởng
A33: T3-004 | B33: T3 | C33: Hỏi đáp gắn SP | D33: Đau lưng thoát vị có nên gần vợ? | E33: Lưng đau mà vợ rủ, làm sao đây? | F33: Phòng ngủ, gối tựa lưng | G33: 19 | H33: =IF($G33="","",IFERROR(INDEX(SAN_PHAM!$D$5:$D$26,MATCH($G33,SAN_PHAM!$A$5:$A$26,0)),"Sai mã SP")) | I33: =IF(OR($G33="",$A33=""),"",IFERROR(INDEX(SAN_PHAM!$L$5:$L$26,MATCH($G33,SAN_PHAM!$A$5:$A$26,0))&"?sub_id=ChiGiang-"&SUBSTITUTE($A33,"-","")&"-FBReels-SP"&TEXT($G33,"00"),"")) | J33: =IF($G33="","",IFERROR(INDEX(SAN_PHAM!$N$5:$N$26,MATCH($G33,SAN_PHAM!$A$5:$A$26,0)),"")) | M33: Ý tưởng
A34: T3-005 | B34: T3 | C34: Review sản phẩm | D34: Review đai lưng tự nóng Kazumi: đau lưng mùa lạnh | E34: Trời trở lạnh, lưng nhức hả mấy anh? | F34: Ghế bố ngoài hiên | G34: 19 | H34: =IF($G34="","",IFERROR(INDEX(SAN_PHAM!$D$5:$D$26,MATCH($G34,SAN_PHAM!$A$5:$A$26,0)),"Sai mã SP")) | I34: =IF(OR($G34="",$A34=""),"",IFERROR(INDEX(SAN_PHAM!$L$5:$L$26,MATCH($G34,SAN_PHAM!$A$5:$A$26,0))&"?sub_id=ChiGiang-"&SUBSTITUTE($A34,"-","")&"-FBReels-SP"&TEXT($G34,"00"),"")) | J34: =IF($G34="","",IFERROR(INDEX(SAN_PHAM!$N$5:$N$26,MATCH($G34,SAN_PHAM!$A$5:$A$26,0)),"")) | M34: Ý tưởng
A35: T3-006 | B35: T3 | C35: Hỏi đáp gắn SP | D35: Đêm chuột rút bắp chân là thiếu gì? | E35: Đang ngủ bị vọp bẻ, anh làm gì đầu tiên? | F35: Phòng ngủ ban đêm | G35: 15 | H35: =IF($G35="","",IFERROR(INDEX(SAN_PHAM!$D$5:$D$26,MATCH($G35,SAN_PHAM!$A$5:$A$26,0)),"Sai mã SP")) | I35: =IF(OR($G35="",$A35=""),"",IFERROR(INDEX(SAN_PHAM!$L$5:$L$26,MATCH($G35,SAN_PHAM!$A$5:$A$26,0))&"?sub_id=ChiGiang-"&SUBSTITUTE($A35,"-","")&"-FBReels-SP"&TEXT($G35,"00"),"")) | J35: =IF($G35="","",IFERROR(INDEX(SAN_PHAM!$N$5:$N$26,MATCH($G35,SAN_PHAM!$A$5:$A$26,0)),"")) | M35: Ý tưởng
